Workbook

Sheet JAN
A1: HISTORICO | B1: DATA COMPETENCIA | C1: CONTA CONTABIL | D1: BROKER | E1: VALOR | F1: FORNECEDOR | G1: DATA LANCAMENTO | H1: CLIENTE | I1: ( | J1: DESPESA DE REPRESENTAÇÃO - | K1: CODIGO | L1: CONVIDADO | M1: CARGO DO CONVIDADO | N1: RAZÃO SOCIAL
A2: =CONCATENATE($J$1,J2,$I$3,M2,$I$3,L2,$I$1,K2,$I$2) -> DESPESA DE REPRESENTAÇÃO - 1/4 PARCELA DO BOX DO RIO OPEN 2026--FILHO DO ERMINIO (AGENDA 38499) | B2: 46023 | C2: 817991 | D2: ERMINIO OLIVI LUCCI | E2: -868 | F2: EVENTO | G2: 45966 | H2: 1170 | I2: ) | J2: 1/4 PARCELA DO BOX DO RIO OPEN 2026 | K2: AGENDA 38499 | L2: FILHO DO ERMINIO | N2: =VLOOKUP(H2,Clientes!B:D,3,) -> BGC LIQUIDEZ DTVM LTDA | P2: =_xlfn.XLOOKUP(K2,#REF!,#REF!,0,0,1) -> #REF!
A3: =CONCATENATE($J$1,J3,$I$3,M3,$I$3,L3,$I$1,K3,$I$2) -> DESPESA DE REPRESENTAÇÃO - 1/4 PARCELA DO BOX DO RIO OPEN 2026--AMIGO DO FILHO DO ERMINIO (AGENDA 38499) | B3: 46023 | C3: 817991 | D3: ERMINIO OLIVI LUCCI | E3: -868 | F3: EVENTO | G3: 45966 | H3: 1170 | I3: - | J3: 1/4 PARCELA DO BOX DO RIO OPEN 2026 | K3: AGENDA 38499 | L3: AMIGO DO FILHO DO ERMINIO | N3: =VLOOKUP(H3,Clientes!B:D,3,) -> BGC LIQUIDEZ DTVM LTDA | P3: =_xlfn.XLOOKUP(K3,#REF!,#REF!,0,0,1) -> #REF!
A4: =CONCATENATE($J$1,J4,$I$3,M4,$I$3,L4,$I$1,K4,$I$2) -> DESPESA DE REPRESENTAÇÃO - 1/4 PARCELA DO BOX DO RIO OPEN 2026-TRADER-PATRICK GRANDMASSON CROCKETT C (AGENDA 38499) | B4: 46023 | C4: 817991 | D4: RICARDO FERREIRA DA COSTA | E4: -868 | F4: EVENTO | G4: 45966 | H4: 14498 | J4: 1/4 PARCELA DO BOX DO RIO OPEN 2026 | K4: AGENDA 38499 | L4: PATRICK GRANDMASSON CROCKETT C | M4: TRADER | N4: =VLOOKUP(H4,Clientes!B:D,3,) -> BANCO BOCOM BBM S/A | P4: =_xlfn.XLOOKUP(K4,#REF!,#REF!,0,0,1) -> #REF!
A5: =CONCATENATE($J$1,J5,$I$3,M5,$I$3,L5,$I$1,K5,$I$2) -> DESPESA DE REPRESENTAÇÃO - 1/4 PARCELA DO BOX DO RIO OPEN 2026-TRADER-LUCAS BARROS (AGENDA 38499) | B5: 46023 | C5: 817991 | D5: RICARDO FERREIRA DA COSTA | E5: -868 | F5: EVENTO | G5: 45966 | H5: 14498 | J5: 1/4 PARCELA DO BOX DO RIO OPEN 2026 | K5: AGENDA 38499 | L5: LUCAS BARROS | M5: TRADER | N5: =VLOOKUP(H5,Clientes!B:D,3,) -> BANCO BOCOM BBM S/A | P5: =_xlfn.XLOOKUP(K5,#REF!,#REF!,0,0,1) -> #REF!
A6: =CONCATENATE($J$1,J6,$I$3,M6,$I$3,L6,$I$1,K6,$I$2) -> DESPESA DE REPRESENTAÇÃO - 1/4 PARCELA DO BOX DO RIO OPEN 2026-TRADER-JOÃO GROSSO (AGENDA 38499) | B6: 46023 | C6: 817991 | D6: RICARDO FERREIRA DA COSTA | E6: -868 | F6: EVENTO | G6: 45966 | H6: 14498 | J6: 1/4 PARCELA DO BOX DO RIO OPEN 2026 | K6: AGENDA 38499 | L6: JOÃO GROSSO | M6: TRADER | N6: =VLOOKUP(H6,Clientes!B:D,3,) -> BANCO BOCOM BBM S/A | P6: =_xlfn.XLOOKUP(K6,#REF!,#REF!,0,0,1) -> #REF!
A7: =CONCATENATE($J$1,J7,$I$3,M7,$I$3,L7,$I$1,K7,$I$2) -> DESPESA DE REPRESENTAÇÃO - 1/4 PARCELA DO BOX DO RIO OPEN 2026-TRADER-JOAO BESSA (AGENDA 38499) | B7: 46023 | C7: 817991 | D7: RAFAEL TENORIO CAVALCANTI | E7: -992 | F7: EVENTO | G7: 45966 | H7: 14416 | J7: 1/4 PARCELA DO BOX DO RIO OPEN 2026 | K7: AGENDA 38499 | L7: JOAO BESSA | M7: TRADER | N7: =VLOOKUP(H7,Clientes!B:D,3,) -> BANCO JP MORGAN S/A | P7: =_xlfn.XLOOKUP(K7,#REF!,#REF!,0,0,1) -> #REF!
A8: =CONCATENATE($J$1,J8,$I$3,M8,$I$3,L8,$I$1,K8,$I$2) -> DESPESA DE REPRESENTAÇÃO - 1/4 PARCELA DO BOX DO RIO OPEN 2026--NAMORADA DO JOAO BESSA (AGENDA 38499) | B8: 46023 | C8: 817991 | D8: RAFAEL TENORIO CAVALCANTI | E8: -992 | F8: EVENTO | G8: 45966 | H8: 14416 | J8: 1/4 PARCELA DO BOX DO RIO OPEN 2026 | K8: AGENDA 38499 | L8: NAMORADA DO JOAO BESSA | N8: =VLOOKUP(H8,Clientes!B:D,3,) -> BANCO JP MORGAN S/A | P8: =_xlfn.XLOOKUP(K8,#REF!,#REF!,0,0,1) -> #REF!
A9: =CONCATENATE($J$1,J9,$I$3,M9,$I$3,L9,$I$1,K9,$I$2) -> DESPESA DE REPRESENTAÇÃO - 1/4 PARCELA DO BOX DO RIO OPEN 2026-TRADER-FELIPE NOVAIS GARCIA (AGENDA 38499) | B9: 46023 | C9: 817991 | D9: ANTONIO AUGUSTO DAS CHAGAS CARVALHO | E9: -992 | F9: EVENTO | G9: 45966 | H9: 80573 | J9: 1/4 PARCELA DO BOX DO RIO OPEN 2026 | K9: AGENDA 38499 | L9: FELIPE NOVAIS GARCIA | M9: TRADER | N9: =VLOOKUP(H9,Clientes!B:D,3,) -> BANCO C6 S/A | P9: =_xlfn.XLOOKUP(K9,#REF!,#REF!,0,0,1) -> #REF!
A10: =CONCATENATE($J$1,J10,$I$3,M10,$I$3,L10,$I$1,K10,$I$2) -> DESPESA DE REPRESENTAÇÃO - 1/4 PARCELA DO BOX DO RIO OPEN 2026-TRADER-MARCELO ORTEGA (AGENDA 38499) | B10: 46023 | C10: 817991 | D10: ANTONIO AUGUSTO DAS CHAGAS CARVALHO | E10: -992 | F10: EVENTO | G10: 45966 | H10: 80573 | J10: 1/4 PARCELA DO BOX DO RIO OPEN 2026 | K10: AGENDA 38499 | L10: MARCELO ORTEGA | M10: TRADER | N10: =VLOOKUP(H10,Clientes!B:D,3,) -> BANCO C6 S/A | P10: =_xlfn.XLOOKUP(K10,#REF!,#REF!,0,0,1) -> #REF!
A11: =CONCATENATE($J$1,J11,$I$3,M11,$I$3,L11,$I$1,K11,$I$2) -> DESPESA DE REPRESENTAÇÃO - 1/4 PARCELA DO BOX DO RIO OPEN 2026-TRADER-LUCIANA GARCIA (AGENDA 38499) | B11: 46023 | C11: 817991 | D11: ANTONIO AUGUSTO DAS CHAGAS CARVALHO | E11: -992 | F11: EVENTO | G11: 45966 | H11: 80573 | J11: 1/4 PARCELA DO BOX DO RIO OPEN 2026 | K11: AGENDA 38499 | L11: LUCIANA GARCIA | M11: TRADER | N11: =VLOOKUP(H11,Clientes!B:D,3,) -> BANCO C6 S/A | P11: =_xlfn.XLOOKUP(K11,#REF!,#REF!,0,0,1) -> #REF!
A12: =CONCATENATE($J$1,J12,$I$3,M12,$I$3,L12,$I$1,K12,$I$2) -> DESPESA DE REPRESENTAÇÃO - 1/4 PARCELA DO BOX DO RIO OPEN 2026-TRADER-DIEGO MONT - STAR SEGURADORA (AGENDA 38499) | B12: 46023 | C12: 817991 | D12: JUAREZ JOAQUIM DE LACERDA | E12: -1116 | F12: EVENTO | G12: 45966 | H12: 1170 | J12: 1/4 PARCELA DO BOX DO RIO OPEN 2026 | K12: AGENDA 38499 | L12: DIEGO MONT - STAR SEGURADORA | M12: TRADER | N12: =VLOOKUP(H12,Clientes!B:D,3,) -> BGC LIQUIDEZ DTVM LTDA | P12: =_xlfn.XLOOKUP(K12,#REF!,#REF!,0,0,1) -> #REF!
A13: =CONCATENATE($J$1,J13,$I$3,M13,$I$3,L13,$I$1,K13,$I$2) -> DESPESA DE REPRESENTAÇÃO - 1/4 PARCELA DO BOX DO RIO OPEN 2026--ESPOSA DO DIEGO MONT - STAR SEGURADORA (AGENDA 38499) | B13: 46023 | C13: 817991 | D13: JUAREZ JOAQUIM DE LACERDA | E13: -1116 | F13: EVENTO | G13: 45966 | H13: 1170 | J13: 1/4 PARCELA DO BOX DO RIO OPEN 2026 | K13: AGENDA 38499 | L13: ESPOSA DO DIEGO MONT - STAR SEGURADORA | N13: =VLOOKUP(H13,Clientes!B:D,3,) -> BGC LIQUIDEZ DTVM LTDA | P13: =_xlfn.XLOOKUP(K13,#REF!,#REF!,0,0,1) -> #REF!
A14: =CONCATENATE($J$1,J14,$I$3,M14,$I$3,L14,$I$1,K14,$I$2) -> DESPESA DE REPRESENTAÇÃO - 1/4 PARCELA DO BOX DO RIO OPEN 2026-TRADER-MARCOS DE CASTRO LOPEZ (AGENDA 38499) | B14: 46023 | C14: 817991 | D14: GUSTAVO D ELBOUX FERRIELLO | E14: -1116 | F14: EVENTO | G14: 45966 | H14: 12413 | J14: 1/4 PARCELA DO BOX DO RIO OPEN 2026 | K14: AGENDA 38499 | L14: MARCOS DE CASTRO LOPEZ | M14: TRADER | N14: =VLOOKUP(H14,Clientes!B:D,3,) -> KAPITALO INVESTIMENTOS LTDA | P14: =_xlfn.XLOOKUP(K14,#REF!,#REF!,0,0,1) -> #REF!
A15: =CONCATENATE($J$1,J15,$I$3,M15,$I$3,L15,$I$1,K15,$I$2) -> DESPESA DE REPRESENTAÇÃO - 1/4 PARCELA DO BOX DO RIO OPEN 2026--ESPOSA DO MARCOS DE CASTRO LOPEZ (AGENDA 38499) | B15: 46023 | C15: 817991 | D15: GUSTAVO D ELBOUX FERRIELLO | E15: -1116 | F15: EVENTO | G15: 45966 | H15: 12413 | J15: 1/4 PARCELA DO BOX DO RIO OPEN 2026 | K15: AGENDA 38499 | L15: ESPOSA DO MARCOS DE CASTRO LOPEZ | N15: =VLOOKUP(H15,Clientes!B:D,3,) -> KAPITALO INVESTIMENTOS LTDA | P15: =_xlfn.XLOOKUP(K15,#REF!,#REF!,0,0,1) -> #REF!
A16: =CONCATENATE($J$1,J16,$I$3,M16,$I$3,L16,$I$1,K16,$I$2) -> DESPESA DE REPRESENTAÇÃO - 1/4 PARCELA DO BOX DO RIO OPEN 2026--FILHO DO MARCOS DE CASTRO LOPEZ (AGENDA 38499) | B16: 46023 | C16: 817991 | D16: GUSTAVO D ELBOUX FERRIELLO | E16: -1116 | F16: EVENTO | G16: 45966 | H16: 12413 | J16: 1/4 PARCELA DO BOX DO RIO OPEN 2026 | K16: AGENDA 38499 | L16: FILHO DO MARCOS DE CASTRO LOPEZ | N16: =VLOOKUP(H16,Clientes!B:D,3,) -> KAPITALO INVESTIMENTOS LTDA | P16: =_xlfn.XLOOKUP(K16,#REF!,#REF!,0,0,1) -> #REF!
A17: =CONCATENATE($J$1,J17,$I$3,M17,$I$3,L17,$I$1,K17,$I$2) -> DESPESA DE REPRESENTAÇÃO - 1/4 PARCELA DO BOX DO RIO OPEN 2026-TRADER-BRUNO PAULO (AGENDA 38499) | B17: 46023 | C17: 817991 | D17: CESAR MARIANO SCARAMBONE MENEZES | E17: -124 | F17: EVENTO | G17: 45966 | H17: 83063 | J17: 1/4 PARCELA DO BOX DO RIO OPEN 2026 | K17: AGENDA 38499 | L17: BRUNO PAULO | M17: TRADER | N17: =VLOOKUP(H17,Clientes!B:D,3,) -> SCHONFELD STRATEGIC ADVISORS BRAZIL LTDA. | P17: =_xlfn.XLOOKUP(K17,#REF!,#REF!,0,0,1) -> #REF!
A18: =CONCATENATE($J$1,J18,$I$3,M18,$I$3,L18,$I$1,K18,$I$2) -> DESPESA DE REPRESENTAÇÃO - 1/4 PARCELA DO BOX DO RIO OPEN 2026--FILHA DO BRUNO PAULO (AGENDA 38499) | B18: 46023 | C18: 817991 | D18: CESAR MARIANO SCARAMBONE MENEZES | E18: -124 | F18: EVENTO | G18: 45966 | H18: 83063 | J18: 1/4 PARCELA DO BOX DO RIO OPEN 2026 | K18: AGENDA 38499 | L18: FILHA DO BRUNO PAULO | N18: =VLOOKUP(H18,Clientes!B:D,3,) -> SCHONFELD STRATEGIC ADVISORS BRAZIL LTDA. | P18: =_xlfn.XLOOKUP(K18,#REF!,#REF!,0,0,1) -> #REF!
A19: =CONCATENATE($J$1,J19,$I$3,M19,$I$3,L19,$I$1,K19,$I$2) -> DESPESA DE REPRESENTAÇÃO - 1/4 PARCELA DO BOX DO RIO OPEN 2026-TRADER-ANDRE LOBATO PINHEIRO (AGENDA 38499) | B19: 46023 | C19: 817991 | D19: ALEXANDRE DA COSTA SOARES | E19: -124 | F19: EVENTO | G19: 45966 | H19: 15501 | J19: 1/4 PARCELA DO BOX DO RIO OPEN 2026 | K19: AGENDA 38499 | L19: ANDRE LOBATO PINHEIRO | M19: TRADER | N19: =VLOOKUP(H19,Clientes!B:D,3,) -> BANCO BTG PACTUAL S/A | P19: =_xlfn.XLOOKUP(K19,#REF!,#REF!,0,0,1) -> #REF!
A20: =CONCATENATE($J$1,J20,$I$3,M20,$I$3,L20,$I$1,K20,$I$2) -> DESPESA DE REPRESENTAÇÃO - 1/4 PARCELA DO BOX DO RIO OPEN 2026--ESPOSA DO ANDRE LOBATO PINHEIRO (AGENDA 38499) | B20: 46023 | C20: 817991 | D20: ALEXANDRE DA COSTA SOARES | E20: -124 | F20: EVENTO | G20: 45966 | H20: 15501 | J20: 1/4 PARCELA DO BOX DO RIO OPEN 2026 | K20: AGENDA 38499 | L20: ESPOSA DO ANDRE LOBATO PINHEIRO | N20: =VLOOKUP(H20,Clientes!B:D,3,) -> BANCO BTG PACTUAL S/A | P20: =_xlfn.XLOOKUP(K20,#REF!,#REF!,0,0,1) -> #REF!
A21: =CONCATENATE($J$1,J21,$I$3,M21,$I$3,L21,$I$1,K21,$I$2) -> DESPESA DE REPRESENTAÇÃO - 1/4 PARCELA DO BOX DO RIO OPEN 2026-TRADER-HENRIQUE DE LA ROCQUE (AGENDA 38499) | B21: 46023 | C21: 817991 | D21: JOSE MAURICIO GOMES TEIXEIRA | E21: -124 | F21: EVENTO | G21: 45966 | H21: 125119 | J21: 1/4 PARCELA DO BOX DO RIO OPEN 2026 | K21: AGENDA 38499 | L21: HENRIQUE DE LA ROCQUE | M21: TRADER | N21: =VLOOKUP(H21,Clientes!B:D,3,) -> IRB ASSET MANAGEMENT S.A | P21: =_xlfn.XLOOKUP(K21,#REF!,#REF!,0,0,1) -> #REF!
A22: =CONCATENATE($J$1,J22,$I$3,M22,$I$3,L22,$I$1,K22,$I$2) -> DESPESA DE REPRESENTAÇÃO - 2/4 PARCELA DO BOX DO RIO OPEN 2026-TRADER-BRUNO PAULO (AGENDA 38500) | B22: 46023 | C22: 817991 | D22: CESAR MARIANO SCARAMBONE MENEZES | E22: -1116 | F22: EVENTO | G22: 45996 | H22: 83063 | J22: 2/4 PARCELA DO BOX DO RIO OPEN 2026 | K22: AGENDA 38500 | L22: BRUNO PAULO | M22: TRADER | N22: =VLOOKUP(H22,Clientes!B:D,3,) -> SCHONFELD STRATEGIC ADVISORS BRAZIL LTDA. | P22: =_xlfn.XLOOKUP(K22,#REF!,#REF!,0,0,1) -> #REF!
A23: =CONCATENATE($J$1,J23,$I$3,M23,$I$3,L23,$I$1,K23,$I$2) -> DESPESA DE REPRESENTAÇÃO - 2/4 PARCELA DO BOX DO RIO OPEN 2026--FILHA DO BRUNO PAULO (AGENDA 38500) | B23: 46023 | C23: 817991 | D23: CESAR MARIANO SCARAMBONE MENEZES | E23: -1116 | F23: EVENTO | G23: 45996 | H23: 83063 | J23: 2/4 PARCELA DO BOX DO RIO OPEN 2026 | K23: AGENDA 38500 | L23: FILHA DO BRUNO PAULO | N23: =VLOOKUP(H23,Clientes!B:D,3,) -> SCHONFELD STRATEGIC ADVISORS BRAZIL LTDA. | P23: =_xlfn.XLOOKUP(K23,#REF!,#REF!,0,0,1) -> #REF!
A24: =CONCATENATE($J$1,J24,$I$3,M24,$I$3,L24,$I$1,K24,$I$2) -> DESPESA DE REPRESENTAÇÃO - 2/4 PARCELA DO BOX DO RIO OPEN 2026-TRADER-ANDRE LOBATO PINHEIRO (AGENDA 38500) | B24: 46023 | C24: 817991 | D24: ALEXANDRE DA COSTA SOARES | E24: -1116 | F24: EVENTO | G24: 45996 | H24: 15501 | J24: 2/4 PARCELA DO BOX DO RIO OPEN 2026 | K24: AGENDA 38500 | L24: ANDRE LOBATO PINHEIRO | M24: TRADER | N24: =VLOOKUP(H24,Clientes!B:D,3,) -> BANCO BTG PACTUAL S/A | P24: =_xlfn.XLOOKUP(K24,#REF!,#REF!,0,0,1) -> #REF!
A25: =CONCATENATE($J$1,J25,$I$3,M25,$I$3,L25,$I$1,K25,$I$2) -> DESPESA DE REPRESENTAÇÃO - 2/4 PARCELA DO BOX DO RIO OPEN 2026--ESPOSA DO ANDRE LOBATO PINHEIRO (AGENDA 38500) | B25: 46023 | C25: 817991 | D25: ALEXANDRE DA COSTA SOARES | E25: -1116 | F25: EVENTO | G25: 45996 | H25: 15501 | J25: 2/4 PARCELA DO BOX DO RIO OPEN 2026 | K25: AGENDA 38500 | L25: ESPOSA DO ANDRE LOBATO PINHEIRO | N25: =VLOOKUP(H25,Clientes!B:D,3,) -> BANCO BTG PACTUAL S/A | P25: =_xlfn.XLOOKUP(K25,#REF!,#REF!,0,0,1) -> #REF!
A26: =CONCATENATE($J$1,J26,$I$3,M26,$I$3,L26,$I$1,K26,$I$2) -> DESPESA DE REPRESENTAÇÃO - 2/4 PARCELA DO BOX DO RIO OPEN 2026-TRADER-HENRIQUE DE LA ROCQUE (AGENDA 38500) | B26: 46023 | C26: 817991 | D26: JOSE MAURICIO GOMES TEIXEIRA | E26: -1116 | F26: EVENTO | G26: 45996 | H26: 125119 | J26: 2/4 PARCELA DO BOX DO RIO OPEN 2026 | K26: AGENDA 38500 | L26: HENRIQUE DE LA ROCQUE | M26: TRADER | N26: =VLOOKUP(H26,Clientes!B:D,3,) -> IRB ASSET MANAGEMENT S.A | P26: =_xlfn.XLOOKUP(K26,#REF!,#REF!,0,0,1) -> #REF!
A27: =CONCATENATE($J$1,J27,$I$3,M27,$I$3,L27,$I$1,K27,$I$2) -> DESPESA DE REPRESENTAÇÃO - 2/4 PARCELA DO BOX DO RIO OPEN 2026-TRADER-MARCOS DE CASTRO LOPEZ (AGENDA 38500) | B27: 46023 | C27: 817991 | D27: GUSTAVO D ELBOUX FERRIELLO | E27: -1860 | F27: EVENTO | G27: 45996 | H27: 12413 | J27: 2/4 PARCELA DO BOX DO RIO OPEN 2026 | K27: AGENDA 38500 | L27: MARCOS DE CASTRO LOPEZ | M27: TRADER | N27: =VLOOKUP(H27,Clientes!B:D,3,) -> KAPITALO INVESTIMENTOS LTDA | P27: =_xlfn.XLOOKUP(K27,#REF!,#REF!,0,0,1) -> #REF!
A28: =CONCATENATE($J$1,J28,$I$3,M28,$I$3,L28,$I$1,K28,$I$2) -> DESPESA DE REPRESENTAÇÃO - 2/4 PARCELA DO BOX DO RIO OPEN 2026--ESPOSA DO MARCOS DE CASTRO LOPEZ (AGENDA 38500) | B28: 46023 | C28: 817991 | D28: GUSTAVO D ELBOUX FERRIELLO | E28: -1860 | F28: EVENTO | G28: 45996 | H28: 12413 | J28: 2/4 PARCELA DO BOX DO RIO OPEN 2026 | K28: AGENDA 38500 | L28: ESPOSA DO MARCOS DE CASTRO LOPEZ | N28: =VLOOKUP(H28,Clientes!B:D,3,) -> KAPITALO INVESTIMENTOS LTDA | P28: =_xlfn.XLOOKUP(K28,#REF!,#REF!,0,0,1) -> #REF!
A29: =CONCATENATE($J$1,J29,$I$3,M29,$I$3,L29,$I$1,K29,$I$2) -> DESPESA DE REPRESENTAÇÃO - 2/4 PARCELA DO BOX DO RIO OPEN 2026-TRADER-FELIPE SANTANA DA SILVEIRA (AGENDA 38500) | B29: 46023 | C29: 817991 | D29: ANTÔNIO MARTINS NETO | E29: -1860 | F29: EVENTO | G29: 45996 | H29: 80958 | J29: 2/4 PARCELA DO BOX DO RIO OPEN 2026 | K29: AGENDA 38500 | L29: FELIPE SANTANA DA SILVEIRA | M29: TRADER | N29: =VLOOKUP(H29,Clientes!B:D,3,) -> ITAU UNIBANCO ASSET - OPTIMUS | P29: =_xlfn.XLOOKUP(K29,#REF!,#REF!,0,0,1) -> #REF!
A30: =CONCATENATE($J$1,J30,$I$3,M30,$I$3,L30,$I$1,K30,$I$2) -> DESPESA DE REPRESENTAÇÃO - 2/4 PARCELA DO BOX DO RIO OPEN 2026--ESPOSA DO FELIPE SANTANA DA SILVEIRA (AGENDA 38500) | B30: 46023 | C30: 817991 | D30: ANTÔNIO MARTINS NETO | E30: -1860 | F30: EVENTO | G30: 45996 | H30: 80958 | J30: 2/4 PARCELA DO BOX DO RIO OPEN 2026 | K30: AGENDA 38500 | L30: ESPOSA DO FELIPE SANTANA DA SILVEIRA | N30: =VLOOKUP(H30,Clientes!B:D,3,) -> ITAU UNIBANCO ASSET - OPTIMUS | P30: =_xlfn.XLOOKUP(K30,#REF!,#REF!,0,0,1) -> #REF!
A31: =CONCATENATE($J$1,J31,$I$3,M31,$I$3,L31,$I$1,K31,$I$2) -> DESPESA DE REPRESENTAÇÃO - 2/4 PARCELA DO BOX DO RIO OPEN 2026-TRADER-GUSTAVO MORAIS SILVA (AGENDA 38500) | B31: 46023 | C31: 817991 | D31: ENRICO BORTPLUZO CASSIANO | E31: -1860 | F31: EVENTO | G31: 45996 | H31: 79372 | J31: 2/4 PARCELA DO BOX DO RIO OPEN 2026 | K31: AGENDA 38500 | L31: GUSTAVO MORAIS SILVA | M31: TRADER | N31: =VLOOKUP(H31,Clientes!B:D,3,) -> ICATU VANGUARDA GESTAO DE RECURSOS LTDA | P31: =_xlfn.XLOOKUP(K31,#REF!,#REF!,0,0,1) -> #REF!
A32: =CONCATENATE($J$1,J32,$I$3,M32,$I$3,L32,$I$1,K32,$I$2) -> DESPESA DE REPRESENTAÇÃO - 2/4 PARCELA DO BOX DO RIO OPEN 2026-TRADER-FERNANDO SCARPA R LEITE (AGENDA 38500) | B32: 46023 | C32: 817991 | D32: FELIPE MEIRELLES RACCAH | E32: -124 | F32: EVENTO | G32: 45996 | H32: 80375 | J32: 2/4 PARCELA DO BOX DO RIO OPEN 2026 | K32: AGENDA 38500 | L32: FERNANDO SCARPA R LEITE | M32: TRADER | N32: =VLOOKUP(H32,Clientes!B:D,3,) -> ITAU UNIBANCO S/A | P32: =_xlfn.XLOOKUP(K32,#REF!,#REF!,0,0,1) -> #REF!
A33: =CONCATENATE($J$1,J33,$I$3,M33,$I$3,L33,$I$1,K33,$I$2) -> DESPESA DE REPRESENTAÇÃO - 2/4 PARCELA DO BOX DO RIO OPEN 2026--FILHA DO FERNANDO SCARPA R LEITE (AGENDA 38500) | B33: 46023 | C33: 817991 | D33: FELIPE MEIRELLES RACCAH | E33: -124 | F33: EVENTO | G33: 45996 | H33: 80375 | J33: 2/4 PARCELA DO BOX DO RIO OPEN 2026 | K33: AGENDA 38500 | L33: FILHA DO FERNANDO SCARPA R LEITE | N33: =VLOOKUP(H33,Clientes!B:D,3,) -> ITAU UNIBANCO S/A | P33: =_xlfn.XLOOKUP(K33,#REF!,#REF!,0,0,1) -> #REF!
A34: =CONCATENATE($J$1,J34,$I$3,M34,$I$3,L34,$I$1,K34,$I$2) -> DESPESA DE REPRESENTAÇÃO - 2/4 PARCELA DO BOX DO RIO OPEN 2026-TRADER-LUIZ ALBERTO BASQUEIRA (AGENDA 38500) | B34: 46023 | C34: 817991 | D34: LIQUIDEZ-OTHER | E34: -124 | F34: EVENTO | G34: 45996 | H34: 79931 | J34: 2/4 PARCELA DO BOX DO RIO OPEN 2026 | K34: AGENDA 38500 | L34: LUIZ ALBERTO BASQUEIRA | M34: TRADER | N34: =VLOOKUP(H34,Clientes!B:D,3,) -> SPX GESTAO DE RECURSOS LTDA | P34: =_xlfn.XLOOKUP(K34,#REF!,#REF!,0,0,1) -> #REF!
A35: =CONCATENATE($J$1,J35,$I$3,M35,$I$3,L35,$I$1,K35,$I$2) -> DESPESA DE REPRESENTAÇÃO - 2/4 PARCELA DO BOX DO RIO OPEN 2026-TRADER-RODRIGO FERREIRA (AGENDA 38500) | B35: 46113 | C35: 817991 | D35: CLAUDIO DE SOUZA PACINI | E35: -124 | F35: EVENTO | G35: 45996 | H35: 12413 | J35: 2/4 PARCELA DO BOX DO RIO OPEN 2026 | K35: AGENDA 38500 | L35: RODRIGO FERREIRA | M35: TRADER | N35: =VLOOKUP(H35,Clientes!B:D,3,) -> KAPITALO INVESTIMENTOS LTDA | P35: =_xlfn.XLOOKUP(K35,#REF!,#REF!,0,0,1) -> #REF!
A36: =CONCATENATE($J$1,J36,$I$3,M36,$I$3,L36,$I$1,K36,$I$2) -> DESPESA DE REPRESENTAÇÃO - 2/4 PARCELA DO BOX DO RIO OPEN 2026--ESPOSA RODRIGO FERREIRA (AGENDA 38500) | B36: 46113 | C36: 817991 | D36: CLAUDIO DE SOUZA PACINI | E36: -124 | F36: EVENTO | G36: 45996 | H36: 12413 | J36: 2/4 PARCELA DO BOX DO RIO OPEN 2026 | K36: AGENDA 38500 | L36: ESPOSA RODRIGO FERREIRA | N36: =VLOOKUP(H36,Clientes!B:D,3,) -> KAPITALO INVESTIMENTOS LTDA | P36: =_xlfn.XLOOKUP(K36,#REF!,#REF!,0,0,1) -> #REF!
A37: =CONCATENATE($J$1,J37,$I$3,M37,$I$3,L37,$I$1,K37,$I$2) -> DESPESA DE REPRESENTAÇÃO - 3/4 PARCELA DO BOX DO RIO OPEN 2026-TRADER-FERNANDO SCARPA R LEITE (AGENDA 38501) | B37: 46023 | C37: 817991 | D37: FELIPE MEIRELLES RACCAH | E37: -2604 | F37: EVENTO | G37: 46027 | H37: 80375 | J37: 3/4 PARCELA DO BOX DO RIO OPEN 2026 | K37: AGENDA 38501 | L37: FERNANDO SCARPA R LEITE | M37: TRADER | N37: =VLOOKUP(H37,Clientes!B:D,3,) -> ITAU UNIBANCO S/A | P37: =_xlfn.XLOOKUP(K37,#REF!,#REF!,0,0,1) -> #REF!
A38: =CONCATENATE($J$1,J38,$I$3,M38,$I$3,L38,$I$1,K38,$I$2) -> DESPESA DE REPRESENTAÇÃO - 3/4 PARCELA DO BOX DO RIO OPEN 2026--FILHA DO FERNANDO SCARPA R LEITE (AGENDA 38501) | B38: 46023 | C38: 817991 | D38: FELIPE MEIRELLES RACCAH | E38: -2604 | F38: EVENTO | G38: 46027 | H38: 80375 | J38: 3/4 PARCELA DO BOX DO RIO OPEN 2026 | K38: AGENDA 38501 | L38: FILHA DO FERNANDO SCARPA R LEITE | N38: =VLOOKUP(H38,Clientes!B:D,3,) -> ITAU UNIBANCO S/A | P38: =_xlfn.XLOOKUP(K38,#REF!,#REF!,0,0,1) -> #REF!
A39: =CONCATENATE($J$1,J39,$I$3,M39,$I$3,L39,$I$1,K39,$I$2) -> DESPESA DE REPRESENTAÇÃO - 3/4 PARCELA DO BOX DO RIO OPEN 2026-TRADER-LUIZ ALBERTO BASQUEIRA (AGENDA 38501) | B39: 46023 | C39: 817991 | D39: LIQUIDEZ-OTHER | E39: -2604 | F39: EVENTO | G39: 46027 | H39: 79931 | J39: 3/4 PARCELA DO BOX DO RIO OPEN 2026 | K39: AGENDA 38501 | L39: LUIZ ALBERTO BASQUEIRA | M39: TRADER | N39: =VLOOKUP(H39,Clientes!B:D,3,) -> SPX GESTAO DE RECURSOS LTDA | P39: =_xlfn.XLOOKUP(K39,#REF!,#REF!,0,0,1) -> #REF!
A40: =CONCATENATE($J$1,J40,$I$3,M40,$I$3,L40,$I$1,K40,$I$2) -> DESPESA DE REPRESENTAÇÃO - 3/4 PARCELA DO BOX DO RIO OPEN 2026-TRADER-RODRIGO FERREIRA (AGENDA 38501) | B40: 46113 | C40: 817991 | D40: CLAUDIO DE SOUZA PACINI | E40: -2604 | F40: EVENTO | G40: 46027 | H40: 12413 | J40: 3/4 PARCELA DO BOX DO RIO OPEN 2026 | K40: AGENDA 38501 | L40: RODRIGO FERREIRA | M40: TRADER | N40: =VLOOKUP(H40,Clientes!B:D,3,) -> KAPITALO INVESTIMENTOS LTDA | P40: =_xlfn.XLOOKUP(K40,#REF!,#REF!,0,0,1) -> #REF!
...

Sheet FEV
A1: HISTORICO | B1: DATA COMPETENCIA | C1: CONTA CONTABIL | D1: BROKER | E1: VALOR | F1: FORNECEDOR | G1: DATA LANCAMENTO | H1: CLIENTE | I1: ( | J1: DESPESA DE REPRESENTAÇÃO - | K1: CODIGO | L1: CONVIDADO | M1: CARGO DO CONVIDADO | N1: RAZÃO SOCIAL
A2: =CONCATENATE($J$1,J2,$I$3,M2,$I$3,L2,$I$1,K2,$I$2) -> DESPESA DE REPRESENTAÇÃO - 4/4 PARCELA DO BOX DO RIO OPEN 2026--ESPOSA DO ANDRE ACCIOLY (AGENDA 38502) | B2: 46054 | C2: 817991 | D2: LIQUIDEZ-OTHER | E2: -3100 | F2: EVENTO | G2: 46058 | H2: 1170 | I2: ) | J2: 4/4 PARCELA DO BOX DO RIO OPEN 2026 | K2: AGENDA 38502 | L2: ESPOSA DO ANDRE ACCIOLY | N2: =VLOOKUP(H2,Clientes!B:D,3,) -> BGC LIQUIDEZ DTVM LTDA
A3: =CONCATENATE($J$1,J3,$I$3,M3,$I$3,L3,$I$1,K3,$I$2) -> DESPESA DE REPRESENTAÇÃO - 4/4 PARCELA DO BOX DO RIO OPEN 2026--FILHO DO ANDRE ACCIOLY (AGENDA 38502) | B3: 46054 | C3: 817991 | D3: LIQUIDEZ-OTHER | E3: -3100 | F3: EVENTO | G3: 46058 | H3: 1170 | I3: - | J3: 4/4 PARCELA DO BOX DO RIO OPEN 2026 | K3: AGENDA 38502 | L3: FILHO DO ANDRE ACCIOLY | N3: =VLOOKUP(H3,Clientes!B:D,3,) -> BGC LIQUIDEZ DTVM LTDA
A4: =CONCATENATE($J$1,J4,$I$3,M4,$I$3,L4,$I$1,K4,$I$2) -> DESPESA DE REPRESENTAÇÃO - 4/4 PARCELA DO BOX DO RIO OPEN 2026-BROKER-JOSE MAURICIO GOMES TEIXEIRA (AGENDA 38502) | B4: 46054 | C4: 817991 | D4: JOSE MAURICIO GOMES TEIXEIRA | E4: -3100 | F4: EVENTO | G4: 46058 | H4: 1170 | J4: 4/4 PARCELA DO BOX DO RIO OPEN 2026 | K4: AGENDA 38502 | L4: JOSE MAURICIO GOMES TEIXEIRA | M4: BROKER | N4: =VLOOKUP(H4,Clientes!B:D,3,) -> BGC LIQUIDEZ DTVM LTDA
A5: =CONCATENATE($J$1,J5,$I$3,M5,$I$3,L5,$I$1,K5,$I$2) -> DESPESA DE REPRESENTAÇÃO - 4/4 PARCELA DO BOX DO RIO OPEN 2026--ESPOSA DO JOSE MAURICIO GOMES TEIXEIRA (AGENDA 38502) | B5: 46054 | C5: 817991 | D5: JOSE MAURICIO GOMES TEIXEIRA | E5: -3100 | F5: EVENTO | G5: 46058 | H5: 1170 | J5: 4/4 PARCELA DO BOX DO RIO OPEN 2026 | K5: AGENDA 38502 | L5: ESPOSA DO JOSE MAURICIO GOMES TEIXEIRA | N5: =VLOOKUP(H5,Clientes!B:D,3,) -> BGC LIQUIDEZ DTVM LTDA
A6: =CONCATENATE($J$1,J6,$I$3,M6,$I$3,L6,$I$1,K6,$I$2) -> DESPESA DE REPRESENTAÇÃO - 4/4 PARCELA DO BOX DO RIO OPEN 2026-TRADER-LUAN VALENTE (AGENDA 38502) | B6: 46054 | C6: 817991 | D6: JOSE MAURICIO GOMES TEIXEIRA | E6: -3100 | F6: EVENTO | G6: 46058 | H6: 80132 | J6: 4/4 PARCELA DO BOX DO RIO OPEN 2026 | K6: AGENDA 38502 | L6: LUAN VALENTE | M6: TRADER | N6: =VLOOKUP(H6,Clientes!B:D,3,) -> GLOBO COMUNICACAO E PARTICIPACOES S.A
A7: =CONCATENATE($J$1,J7,$I$3,M7,$I$3,L7,$I$1,K7,$I$2) -> DESPESA DE REPRESENTAÇÃO - ALMOÇO -TRADER-RAFAEL PERES NABESHIMA (102527-3688FR) | B7: 46054 | C7: 817991 | D7: FELIPE MEIRELLES RACCAH | E7: -943.66 | F7: ALMOÇO | G7: 46058 | H7: 80375 | J7: ALMOÇO | K7: 102527-3688FR | L7: RAFAEL PERES NABESHIMA | M7: TRADER | N7: =VLOOKUP(H7,Clientes!B:D,3,) -> ITAU UNIBANCO S/A
A8: =CONCATENATE($J$1,J8,$I$3,M8,$I$3,L8,$I$1,K8,$I$2) -> DESPESA DE REPRESENTAÇÃO - HAPPY HOUR-TRADER-RODRIGO SANTANA FERREIRA (103534-3688FR) | B8: 46054 | C8: 817991 | D8: FELIPE MEIRELLES RACCAH | E8: -1554.88 | F8: EVENTO | G8: 46058 | H8: 80005 | J8: HAPPY HOUR | K8: 103534-3688FR | L8: RODRIGO SANTANA FERREIRA | M8: TRADER | N8: =VLOOKUP(H8,Clientes!B:D,3,) -> DEUTSCHE BANK S/A
A9: =CONCATENATE($J$1,J9,$I$3,M9,$I$3,L9,$I$1,K9,$I$2) -> DESPESA DE REPRESENTAÇÃO - HAPPY HOUR-TRADER-HENRIQUE TEIXEIRA CASTAGNET (103728-3688AA) | B9: 46054 | C9: 817991 | D9: ANTONIO AGIZ FILHO | E9: -714 | F9: EVENTO | G9: 46058 | H9: 83577 | J9: HAPPY HOUR | K9: 103728-3688AA | L9: HENRIQUE TEIXEIRA CASTAGNET | M9: TRADER | N9: =VLOOKUP(H9,Clientes!B:D,3,) -> BANCO MIZUHO DO BRASIL S/A
A10: =CONCATENATE($J$1,J10,$I$3,M10,$I$3,L10,$I$1,K10,$I$2) -> DESPESA DE REPRESENTAÇÃO - HAPPY HOUR-TRADER-MARCELO SCHOLZ ISSA (103235-3688AA) | B10: 46054 | C10: 817991 | D10: ANTONIO AGIZ FILHO | E10: -406 | F10: EVENTO | G10: 46058 | H10: 81259 | J10: HAPPY HOUR | K10: 103235-3688AA | L10: MARCELO SCHOLZ ISSA | M10: TRADER | N10: =VLOOKUP(H10,Clientes!B:D,3,) -> GOLDMAN SACHS DO BRASIL BANCO MULTIPLO S/A
A11: =CONCATENATE($J$1,J11,$I$3,M11,$I$3,L11,$I$1,K11,$I$2) -> DESPESA DE REPRESENTAÇÃO - ALMOÇO -TRADER-DANILO BASTOS GALVÃO (162755-3688BG) | B11: 46054 | C11: 817991 | D11: JOSE MAURICIO GOMES TEIXEIRA | E11: -1197.8 | F11: ALMOÇO | G11: 46058 | H11: 12402 | J11: ALMOÇO | K11: 162755-3688BG | L11: DANILO BASTOS GALVÃO | M11: TRADER | N11: =VLOOKUP(H11,Clientes!B:D,3,) -> TRUXT INVESTIMENTOS LTDA
A12: =CONCATENATE($J$1,J12,$I$3,M12,$I$3,L12,$I$1,K12,$I$2) -> DESPESA DE REPRESENTAÇÃO - ALMOÇO -TRADER-BENY (140730-3688RP) | B12: 46054 | C12: 817991 | D12: RODRIGO PENTAGNA | E12: -449 | F12: ALMOÇO | G12: 46058 | H12: 81319 | J12: ALMOÇO | K12: 140730-3688RP | L12: BENY | M12: TRADER | N12: =VLOOKUP(H12,Clientes!B:D,3,) -> PRAGMA GESTAO DE PATRIMONIO LTDA
A13: =CONCATENATE($J$1,J13,$I$3,M13,$I$3,L13,$I$1,K13,$I$2) -> DESPESA DE REPRESENTAÇÃO - ALMOÇO -TRADER-LEONARDO AKIRA IZUKA (174940-3688MN) | B13: 46054 | C13: 817991 | D13: CHRISTIANO MARCONDES DE BARROS LIMA | E13: -661.84 | F13: ALMOÇO | G13: 46058 | H13: 82053 | J13: ALMOÇO | K13: 174940-3688MN | L13: LEONARDO AKIRA IZUKA | M13: TRADER | N13: =VLOOKUP(H13,Clientes!B:D,3,) -> ITAU UNIBANCO ASSET - LEGEND
A14: =CONCATENATE($J$1,J14,$I$3,M14,$I$3,L14,$I$1,K14,$I$2) -> DESPESA DE REPRESENTAÇÃO - HAPPY HOUR-TRADER-EDUARDO ROSSI MELLO NOGUEIRA (180639-3688MN) | B14: 46054 | C14: 817991 | D14: CHRISTIANO MARCONDES DE BARROS LIMA | E14: -496.16 | F14: EVENTO | G14: 46058 | H14: 81344 | J14: HAPPY HOUR | K14: 180639-3688MN | L14: EDUARDO ROSSI MELLO NOGUEIRA | M14: TRADER | N14: =VLOOKUP(H14,Clientes!B:D,3,) -> TENAX CAPITAL LTDA
A15: =CONCATENATE($J$1,J15,$I$3,M15,$I$3,L15,$I$1,K15,$I$2) -> DESPESA DE REPRESENTAÇÃO - ALMOÇO -TRADER-LUAN DE AGUIAR CORREIA (154918-3688JT) | B15: 46054 | C15: 817991 | D15: JOSE MAURICIO GOMES TEIXEIRA | E15: -756 | F15: ALMOÇO | G15: 46065 | H15: 12416 | J15: ALMOÇO | K15: 154918-3688JT | L15: LUAN DE AGUIAR CORREIA | M15: TRADER | N15: =VLOOKUP(H15,Clientes!B:D,3,) -> MONGERAL AEGON INVESTIMENTOS LTDA
A16: =CONCATENATE($J$1,J16,$I$3,M16,$I$3,L16,$I$1,K16,$I$2) -> DESPESA DE REPRESENTAÇÃO - JANTAR DE COMEMORAÇÃO DA CONQUISTA NA PERMANENCIA DE DEALER-BROKER-BGC SEGUNDA VOLTA (141905-3688RR) | B16: 46054 | C16: 817991 | D16: BGC SEGUNDA VOLTA | E16: -6153.41 | F16: JANTAR | G16: 46065 | H16: 1170 | J16: JANTAR DE COMEMORAÇÃO DA CONQUISTA NA PERMANENCIA DE DEALER | K16: 141905-3688RR | L16: BGC SEGUNDA VOLTA | M16: BROKER | N16: =VLOOKUP(H16,Clientes!B:D,3,) -> BGC LIQUIDEZ DTVM LTDA
A17: =CONCATENATE($J$1,J17,$I$3,M17,$I$3,L17,$I$1,K17,$I$2) -> DESPESA DE REPRESENTAÇÃO - TAXI-BROKER-FREDERICO PADILHA (105319-3688FP) | B17: 46054 | C17: 817991 | D17: CHRISTIANO MARCONDES DE BARROS LIMA | E17: -60 | F17: LOCOMOÇÃO | G17: 46065 | H17: 1170 | J17: TAXI | K17: 105319-3688FP | L17: FREDERICO PADILHA | M17: BROKER | N17: =VLOOKUP(H17,Clientes!B:D,3,) -> BGC LIQUIDEZ DTVM LTDA
... A90: =CONCATENATE($J$1,J90,$I$3,M90,$I$3,L90,$I$1,K90,$I$2) -> DESPESA DE REPRESENTAÇÃO - TRANSPORTE EXECUTIVO MENSAL DE JANEIRO-CEO-ERMINIO OLIVI LUCCI (AGENDA 40273) | B90: 46054 | C90: 817991 | D90: ERMINIO OLIVI LUCCI | E90: -2070 | F90: LOCOMOÇÃO | G90: 46062 | H90: 1170 | J90: TRANSPORTE EXECUTIVO MENSAL DE JANEIRO | K90: AGENDA 40273 | L90: ERMINIO OLIVI LUCCI | M90: CEO | N90: =VLOOKUP(H90,Clientes!B:D,3,) -> BGC LIQUIDEZ DTVM LTDA
A91: =CONCATENATE($J$1,J91,$I$3,M91,$I$3,L91,$I$1,K91,$I$2) -> DESPESA DE REPRESENTAÇÃO - INGRESSOS PARA O SHOW AC/DC --ALEXANDRA BOKEL ESPOSA DO BERNARDO SALGADO (093659-3688AS) | B91: 46054 | C91: 817991 | D91: BRENO MELLO DOS SANTOS | E91: -1651 | F91: EVENTO | G91: 46065 | H91: 15781 | J91: INGRESSOS PARA O SHOW AC/DC | K91: 093659-3688AS | L91: ALEXANDRA BOKEL ESPOSA DO BERNARDO SALGADO | N91: =VLOOKUP(H91,Clientes!B:D,3,) -> BANCO SAFRA S/A
A92: =CONCATENATE($J$1,J92,$I$3,M92,$I$3,L92,$I$1,K92,$I$2) -> DESPESA DE REPRESENTAÇÃO - INGRESSOS PARA O SHOW AC/DC -TRADER-BERNARDO SALGADO (093659-3688AS) | B92: 46054 | C92: 817991 | D92: BRENO MELLO DOS SANTOS | E92: -1651 | F92: EVENTO | G92: 46065 | H92: 15781 | J92: INGRESSOS PARA O SHOW AC/DC | K92: 093659-3688AS | L92: BERNARDO SALGADO | M92: TRADER | N92: =VLOOKUP(H92,Clientes!B:D,3,) -> BANCO SAFRA S/A
A93: =CONCATENATE($J$1,J93,$I$3,M93,$I$3,L93,$I$1,K93,$I$2) -> DESPESA DE REPRESENTAÇÃO - INGRESSOS PARA O SHOW AC/DC -TRADER-FELIPE S UEDA RUSSO MARTINS (180117-3688FC) | B93: 46054 | C93: 817991 | D93: RICARDO FERREIRA DA COSTA | E93: -1641.74 | F93: EVENTO | G93: 46079 | H93: 80343 | J93: INGRESSOS PARA O SHOW AC/DC | K93: 180117-3688FC | L93: FELIPE S UEDA RUSSO MARTINS | M93: TRADER | N93: =VLOOKUP(H93,Clientes!B:D,3,) -> BANCO BS2 S/A
A94: =CONCATENATE($J$1,J94,$I$3,M94,$I$3,L94,$I$1,K94,$I$2) -> DESPESA DE REPRESENTAÇÃO - INGRESSOS PARA O SHOW AC/DC -TRADER-INGRID DE OLIVEIRA PINHEIRO (180117-3688FC) | B94: 46054 | C94: 817991 | D94: RICARDO FERREIRA DA COSTA | E94: -1641.74 | F94: EVENTO | G94: 46079 | H94: 80343 | J94: INGRESSOS PARA O SHOW AC/DC | K94: 180117-3688FC | L94: INGRID DE OLIVEIRA PINHEIRO | M94: TRADER | N94: =VLOOKUP(H94,Clientes!B:D,3,) -> BANCO BS2 S/A
A95: =CONCATENATE($J$1,J95,$I$3,M95,$I$3,L95,$I$1,K95,$I$2) -> DESPESA DE REPRESENTAÇÃO - SINAL CAFÉ DA MANHÃ COM CAIADO NO DIA 09/02 NO LOUP-SALES-JOSE ANTONIO DEZENE JUNIOR (AGENDA 40266) | B95: 46054 | C95: 817991 | D95: JOSE ANTONIO DEZENE JUNIOR | E95: -1299.5 | F95: CAFE DA MANHÃ | G95: 46059 | H95: 1170 | J95: SINAL CAFÉ DA MANHÃ COM CAIADO NO DIA 09/02 NO LOUP | K95: AGENDA 40266 | L95: JOSE ANTONIO DEZENE JUNIOR | M95: SALES | N95: =VLOOKUP(H95,Clientes!B:D,3,) -> BGC LIQUIDEZ DTVM LTDA
A96: =CONCATENATE($J$1,J96,$I$3,M96,$I$3,L96,$I$1,K96,$I$2) -> DESPESA DE REPRESENTAÇÃO - LIBERAÇÃO E RETIRADA DAS AMOSTRAS DE CAMISETA - KART -SALES-JOSE ANTONIO DEZENE JUNIOR (AGENDA 40263) | B96: 46054 | C96: 817991 | D96: JOSE ANTONIO DEZENE JUNIOR | E96: -89 | F96: EVENTO | G96: 46063 | H96: 1170 | J96: LIBERAÇÃO E RETIRADA DAS AMOSTRAS DE CAMISETA - KART | K96: AGENDA 40263 | L96: JOSE ANTONIO DEZENE JUNIOR | M96: SALES | N96: =VLOOKUP(H96,Clientes!B:D,3,) -> BGC LIQUIDEZ DTVM LTDA
A97: =CONCATENATE($J$1,J97,$I$3,M97,$I$3,L97,$I$1,K97,$I$2) -> DESPESA DE REPRESENTAÇÃO - DEVOLUÇÃO DO CARTÃO CORPORATIVO-CEO-ERMINIO OLIVI LUCCI (AGENDA 40421) | B97: 46054 | C97: 817991 | D97: ERMINIO OLIVI LUCCI | E97: 286.32 | F97: OUTROS | G97: 46066 | H97: 1170 | J97: DEVOLUÇÃO DO CARTÃO CORPORATIVO | K97: AGENDA 40421 | L97: ERMINIO OLIVI LUCCI | M97: CEO | N97: =VLOOKUP(H97,Clientes!B:D,3,) -> BGC LIQUIDEZ DTVM LTDA
A98: =CONCATENATE($J$1,J98,$I$3,M98,$I$3,L98,$I$1,K98,$I$2) -> DESPESA DE REPRESENTAÇÃO - DEVOLUÇÃO DOS INGRESSOS DO BOX DO RIO OPEN 2026-CEO-FILHO DO ERMINIO (AGENDA 40417) | B98: 46023 | C98: 817991 | D98: ERMINIO OLIVI LUCCI | E98: 868 | F98: EVENTO | G98: 46066 | H98: 1170 | J98: DEVOLUÇÃO DOS INGRESSOS DO BOX DO RIO OPEN 2026 | K98: AGENDA 40417 | L98: FILHO DO ERMINIO | M98: CEO | N98: =VLOOKUP(H98,Clientes!B:D,3,) -> BGC LIQUIDEZ DTVM LTDA | P98: =_xlfn.XLOOKUP(K98,#REF!,#REF!,0,0,1) -> #REF!
A99: =CONCATENATE($J$1,J99,$I$3,M99,$I$3,L99,$I$1,K99,$I$2) -> DESPESA DE REPRESENTAÇÃO - DEVOLUÇÃO DOS INGRESSOS DO BOX DO RIO OPEN 2026-CEO-AMIGO DO FILHO DO ERMINIO (AGENDA 40417) | B99: 46023 | C99: 817991 | D99: ERMINIO OLIVI LUCCI | E99: 868 | F99: EVENTO | G99: 46066 | H99: 1170 | J99: DEVOLUÇÃO DOS INGRESSOS DO BOX DO RIO OPEN 2026 | K99: AGENDA 40417 | L99: AMIGO DO FILHO DO ERMINIO | M99: CEO | N99: =VLOOKUP(H99,Clientes!B:D,3,) -> BGC LIQUIDEZ DTVM LTDA | P99: =_xlfn.XLOOKUP(K99,#REF!,#REF!,0,0,1) -> #REF!
A100: =CONCATENATE($J$1,J100,$I$3,M100,$I$3,L100,$I$1,K100,$I$2) -> DESPESA DE REPRESENTAÇÃO - DEVOLUÇÃO DA HOSPEDAGEM NO FAIRMONT NO RIO DE JANEIRO-CEO-ERMINIO OLIVI LUCCI (AGENDA 40341) | B100: 46054 | C100: 817991 | D100: ERMINIO OLIVI LUCCI | E100: =4664.4/2 -> 2332.2 | F100: HOSPEDAGEM | G100: 46063 | H100: 1170 | J100: DEVOLUÇÃO DA HOSPEDAGEM NO FAIRMONT NO RIO DE JANEIRO | K100: AGENDA 40341 | L100: ERMINIO OLIVI LUCCI | M100: CEO | N100: =VLOOKUP(H100,Clientes!B:D,3,) -> BGC LIQUIDEZ DTVM LTDA
A101: =CONCATENATE($J$1,J101,$I$3,M101,$I$3,L101,$I$1,K101,$I$2) -> DESPESA DE REPRESENTAÇÃO - REUNIÃO TRAUMANN & SCHONFELD-SALES-JOSE ANTONIO DEZENE JUNIOR (E-MAIL 06/03/2026) | B101: 46054 | C101: 817991 | D101: JOSE ANTONIO DEZENE JUNIOR | E101: -5500 | F101: EVENTO | G101: 46054 | H101: 1170 | J101: REUNIÃO TRAUMANN & SCHONFELD | K101: E-MAIL 06/03/2026 | L101: JOSE ANTONIO DEZENE JUNIOR | M101: SALES | N101: =VLOOKUP(H101,Clientes!B:D,3,) -> BGC LIQUIDEZ DTVM LTDA
A102: =CONCATENATE($J$1,J102,$I$3,M102,$I$3,L102,$I$1,K102,$I$2) -> DESPESA DE REPRESENTAÇÃO - FRETE DOCUMENTAÇÃO-ECONOMISTA-FELIPE DE SA TAVARES (E-MAIL 03/03/2026) | B102: 46054 | C102: 817991 | D102: FELIPE DE SA TAVARES | E102: -16.88 | F102: OUTROS | G102: 46065 | H102: 1170 | J102: FRETE DOCUMENTAÇÃO | K102: E-MAIL 03/03/2026 | L102: FELIPE DE SA TAVARES | M102: ECONOMISTA | N102: =VLOOKUP(H102,Clientes!B:D,3,) -> BGC LIQUIDEZ DTVM LTDA
A103: =CONCATENATE($J$1,J103,$I$3,M103,$I$3,L103,$I$1,K103,$I$2) -> DESPESA DE REPRESENTAÇÃO - FRETE DOCUMENTAÇÃO-ECONOMISTA-CARLOS THADEU DE FREITAS GOMES FILHO (E-MAIL 03/03/2026) | B103: 46054 | C103: 817991 | D103: CARLOS THADEU DE FREITAS GOMES FILHO | E103: -16.88 | F103: OUTROS | G103: 46065 | H103: 1170 | J103: FRETE DOCUMENTAÇÃO | K103: E-MAIL 03/03/2026 | L103: CARLOS THADEU DE FREITAS GOMES FILHO | M103: ECONOMISTA | N103: =VLOOKUP(H103,Clientes!B:D,3,) -> BGC LIQUIDEZ DTVM LTDA
A104: =CONCATENATE($J$1,J104,$I$3,M104,$I$3,L104,$I$1,K104,$I$2) -> DESPESA DE REPRESENTAÇÃO - UBER-BROKER-JUAREZ JOAQUIM DE LACERDA (E-MAIL 20/05/2026) | B104: 46054 | C104: 817991 | D104: JUAREZ JOAQUIM DE LACERDA | E104: -359.96 | F104: LOCOMOÇÃO | G104: 46072 | H104: 1170 | J104: UBER | K104: E-MAIL 20/05/2026 | L104: JUAREZ JOAQUIM DE LACERDA | M104: BROKER | N104: =VLOOKUP(H104,Clientes!B:D,3,) -> BGC LIQUIDEZ DTVM LTDA
A105: =CONCATENATE($J$1,J105,$I$3,M105,$I$3,L105,$I$1,K105,$I$2) -> DESPESA DE REPRESENTAÇÃO - UBER-SALES-MARCELLE DA SILVEIRA GIL CADILHE (E-MAIL 20/05/2026) | B105: 46054 | C105: 817991 | D105: JOSE ANTONIO DEZENE JUNIOR | E105: -678.86 | F105: LOCOMOÇÃO | G105: 46080 | H105: 1170 | J105: UBER | K105: E-MAIL 20/05/2026 | L105: MARCELLE DA SILVEIRA GIL CADILHE | M105: SALES | N105: =VLOOKUP(H105,Clientes!B:D,3,) -> BGC LIQUIDEZ DTVM LTDA
A106: =CONCATENATE($J$1,J106,$I$3,M106,$I$3,L106,$I$1,K106,$I$2) -> DESPESA DE REPRESENTAÇÃO - UBER-SALES-MELISSA LEITE FIGUEIREDO ROCHA (E-MAIL 20/05/2026) | B106: 46054 | C106: 817991 | D106: JOSE ANTONIO DEZENE JUNIOR | E106: -69.61 | F106: LOCOMOÇÃO | G106: 46076 | H106: 1170 | J106: UBER | K106: E-MAIL 20/05/2026 | L106: MELISSA LEITE FIGUEIREDO ROCHA | M106: SALES | N106: =VLOOKUP(H106,Clientes!B:D,3,) -> BGC LIQUIDEZ DTVM LTDA
A107: =CONCATENATE($J$1,J107,$I$3,M107,$I$3,L107,$I$1,K107,$I$2) -> DESPESA DE REPRESENTAÇÃO - PASSAGEM SÃO PAULO X RIO DE JANEIRO-CEO-ERMINIO OLIVI LUCCI (AGENDA 40469) | B107: 46054 | C107: 817991 | D107: ERMINIO OLIVI LUCCI | E107: -2579.47 | F107: LOCOMOÇÃO | G107: 46073 | H107: 1170 | J107: PASSAGEM SÃO PAULO X RIO DE JANEIRO | K107: AGENDA 40469 | L107: ERMINIO OLIVI LUCCI | M107: CEO | N107: =VLOOKUP(H107,Clientes!B:D,3,) -> BGC LIQUIDEZ DTVM LTDA
A108: =CONCATENATE($J$1,J108,$I$3,M108,$I$3,L108,$I$1,K108,$I$2) -> DESPESA DE REPRESENTAÇÃO - PASSAGEM BRASILIA X SÃO PAULO-CONSULTOR-RENAN REIS CRUVINEL (AGENDA 40469) | B108: 46054 | C108: 817991 | D108: RENAN REIS CRUVINEL | E108: -1695.81 | F108: LOCOMOÇÃO | G108: 46073 | H108: 1170 | J108: PASSAGEM BRASILIA X SÃO PAULO | K108: AGENDA 40469 | L108: RENAN REIS CRUVINEL | M108: CONSULTOR | N108: =VLOOKUP(H108,Clientes!B:D,3,) -> BGC LIQUIDEZ DTVM LTDA
A109: =CONCATENATE($J$1,J109,$I$3,M109,$I$3,L109,$I$1,K109,$I$2) -> DESPESA DE REPRESENTAÇÃO - ALUGUEL FLAT -BROKER-PAULO GUILHERME MENEZES FELIX (AGENDA 40247) | B109: 46054 | C109: 817991 | D109: PAULO GUILHERME MENEZES FELIX | E109: -4202 | F109: HOSPEDAGEM | G109: 46077 | H109: 1170 | J109: ALUGUEL FLAT | K109: AGENDA 40247 | L109: PAULO GUILHERME MENEZES FELIX | M109: BROKER | N109: =VLOOKUP(H109,Clientes!B:D,3,) -> BGC LIQUIDEZ DTVM LTDA

Sheet MAR
A1: HISTORICO | B1: DATA COMPETENCIA | C1: CONTA CONTABIL | D1: BROKER | E1: VALOR | F1: FORNECEDOR | G1: DATA LANCAMENTO | H1: CLIENTE | I1: ( | J1: DESPESA DE REPRESENTAÇÃO - | K1: CODIGO | L1: CONVIDADO | M1: CARGO DO CONVIDADO | N1: RAZÃO SOCIAL
A2: =CONCATENATE($J$1,J2,$I$3,M2,$I$3,L2,$I$1,K2,$I$2) -> DESPESA DE REPRESENTAÇÃO - HOSPEDAGEM INDIGO NYC FINANCIAL DISTRICT-BROKER-CLAUDIO DE SOUZA PACINI (AGENDA 40538) | B2: 46082 | C2: 817991 | D2: CLAUDIO DE SOUZA PACINI | E2: -1240 | F2: HOSPEDAGEM | G2: 46086 | H2: 1170 | I2: ) | J2: HOSPEDAGEM INDIGO NYC FINANCIAL DISTRICT | K2: AGENDA 40538 | L2: CLAUDIO DE SOUZA PACINI | M2: BROKER | N2: =VLOOKUP(H2,Clientes!B:D,3,) -> BGC LIQUIDEZ DTVM LTDA
A3: =CONCATENATE($J$1,J3,$I$3,M3,$I$3,L3,$I$1,K3,$I$2) -> DESPESA DE REPRESENTAÇÃO - HOSPEDAGEM RADISSON BLU SÃO PAULO -CONSULTORA -CLAUDIA TAVARES FERNANDES (AGENDA 40539) | B3: 46082 | C3: 817991 | D3: CLAUDIA TAVARES FERNANDES | E3: -1629.6 | F3: HOSPEDAGEM | G3: 46086 | H3: 1170 | I3: - | J3: HOSPEDAGEM RADISSON BLU SÃO PAULO | K3: AGENDA 40539 | L3: CLAUDIA TAVARES FERNANDES | M3: CONSULTORA | N3: =VLOOKUP(H3,Clientes!B:D,3,) -> BGC LIQUIDEZ DTVM LTDA
A4: =CONCATENATE($J$1,J4,$I$3,M4,$I$3,L4,$I$1,K4,$I$2) -> DESPESA DE REPRESENTAÇÃO - PASSAGEM GUARULHOS X NOVA YORK -CEO-ERMINIO OLIVI LUCCI (AGENDA 40595) | B4: 46082 | C4: 817991 | D4: ERMINIO OLIVI LUCCI | E4: -5746.98 | F4: LOCOMOÇÃO | G4: 46086 | H4: 1170 | J4: PASSAGEM GUARULHOS X NOVA YORK | K4: AGENDA 40595 | L4: ERMINIO OLIVI LUCCI | M4: CEO | N4: =VLOOKUP(H4,Clientes!B:D,3,) -> BGC LIQUIDEZ DTVM LTDA
A5: =CONCATENATE($J$1,J5,$I$3,M5,$I$3,L5,$I$1,K5,$I$2) -> DESPESA DE REPRESENTAÇÃO - 2/2 ALUGUEL - KART-SALES-JOSE ANTONIO DEZENE JUNIOR (AGENDA 40613) | B5: 46082 | C5: 817991 | D5: JOSE ANTONIO DEZENE JUNIOR | E5: -15950 | F5: EVENTO | G5: 46092 | H5: 1170 | J5: 2/2 ALUGUEL - KART | K5: AGENDA 40613 | L5: JOSE ANTONIO DEZENE JUNIOR | M5: SALES | N5: =VLOOKUP(H5,Clientes!B:D,3,) -> BGC LIQUIDEZ DTVM LTDA
A6: =CONCATENATE($J$1,J6,$I$3,M6,$I$3,L6,$I$1,K6,$I$2) -> DESPESA DE REPRESENTAÇÃO - ALMOÇO-TRADER-MAURO OKUMA LACERDA (120324-3688CM) | B6: 46082 | C6: 817991 | D6: CESAR MARIANO SCARAMBONE MENEZES | E6: -2670.19 | F6: ALMOÇO | G6: 46086 | H6: 12413 | J6: ALMOÇO | K6: 120324-3688CM | L6: MAURO OKUMA LACERDA | M6: TRADER | N6: =VLOOKUP(H6,Clientes!B:D,3,) -> KAPITALO INVESTIMENTOS LTDA
A7: =CONCATENATE($J$1,J7,$I$3,M7,$I$3,L7,$I$1,K7,$I$2) -> DESPESA DE REPRESENTAÇÃO - HAPPY HOUR COM NOMURA-TRADER -CHIRAG GARG (111847-3688RC) | B7: 46082 | C7: 817991 | D7: RAFAEL TENORIO CAVALCANTI | E7: -1258 | F7: EVENTO | G7: 46086 | H7: 1170 | J7: HAPPY HOUR COM NOMURA | K7: 111847-3688RC | L7: CHIRAG GARG | M7: TRADER | N7: =VLOOKUP(H7,Clientes!B:D,3,) -> BGC LIQUIDEZ DTVM LTDA
A8: =CONCATENATE($J$1,J8,$I$3,M8,$I$3,L8,$I$1,K8,$I$2) -> DESPESA DE REPRESENTAÇÃO - ALMOÇO-TRADER -RABINDER SIRA (110546-3688RC) | B8: 46082 | C8: 817991 | D8: RAFAEL TENORIO CAVALCANTI | E8: -1611 | F8: ALMOÇO | G8: 46086 | H8: 18658 | J8: ALMOÇO | K8: 110546-3688RC | L8: RABINDER SIRA | M8: TRADER | N8: =VLOOKUP(H8,Clientes!B:D,3,) -> SCOTIABANK BRASILS/A BANCO MULTIPLO(ANTIGO DRESDNER BANK BR)
A9: =CONCATENATE($J$1,J9,$I$3,M9,$I$3,L9,$I$1,K9,$I$2) -> DESPESA DE REPRESENTAÇÃO - JANTAR-TRADER -IGNACIO ALDUNATE (111451-3688RC) | B9: 46082 | C9: 817991 | D9: RAFAEL TENORIO CAVALCANTI | E9: -1712 | F9: JANTAR | G9: 46086 | H9: 441000 | J9: JANTAR | K9: 111451-3688RC | L9: IGNACIO ALDUNATE | M9: TRADER | N9: =VLOOKUP(H9,Clientes!B:D,3,) -> BANCO RABOBANK INTERNATIONAL BRASIL S/A
A10: =CONCATENATE($J$1,J10,$I$3,M10,$I$3,L10,$I$1,K10,$I$2) -> DESPESA DE REPRESENTAÇÃO - HOSPEDAGEM CLUB QUARTERS HOTEL NY-BROKER-RAFAEL TENORIO CAVALCANTI (AGENDA 40626) | B10: 46082 | C10: 817991 | D10: RAFAEL TENORIO CAVALCANTI | E10: -5865 | F10: HOSPEDAGEM | G10: 46086 | H10: 1170 | J10: HOSPEDAGEM CLUB QUARTERS HOTEL NY | K10: AGENDA 40626 | L10: RAFAEL TENORIO CAVALCANTI | M10: BROKER | N10: =VLOOKUP(H10,Clientes!B:D,3,) -> BGC LIQUIDEZ DTVM LTDA
A11: =CONCATENATE($J$1,J11,$I$3,M11,$I$3,L11,$I$1,K11,$I$2) -> DESPESA DE REPRESENTAÇÃO - JANTAR COM CLIENTE ING BANK-TRADER-EDUARDO CASTRO (112309-3688RC) | B11: 46082 | C11: 817991 | D11: RAFAEL TENORIO CAVALCANTI | E11: -2328 | F11: JANTAR | G11: 46086 | H11: 1170 | J11: JANTAR COM CLIENTE ING BANK | K11: 112309-3688RC | L11: EDUARDO CASTRO | M11: TRADER | N11: =VLOOKUP(H11,Clientes!B:D,3,) -> BGC LIQUIDEZ DTVM LTDA
A12: =CONCATENATE($J$1,J12,$I$3,M12,$I$3,L12,$I$1,K12,$I$2) -> DESPESA DE REPRESENTAÇÃO - ALMOÇO-TRADER-JOAO PEROLIN FREDERICO TRALLI (104821-3688FP) | B12: 46082 | C12: 817991 | D12: FABIO SOARES PFAENDER | E12: -900.49 | F12: ALMOÇO | G12: 46086 | H12: 16705 | J12: ALMOÇO | K12: 104821-3688FP | L12: JOAO PEROLIN FREDERICO TRALLI | M12: TRADER | N12: =VLOOKUP(H12,Clientes!B:D,3,) -> BANCO BRADESCO S/A
A13: =CONCATENATE($J$1,J13,$I$3,M13,$I$3,L13,$I$1,K13,$I$2) -> DESPESA DE REPRESENTAÇÃO - HAPPY HOUR-TRADER-RUBENS SHIN (114441-3688RC) | B13: 46082 | C13: 817991 | D13: RAFAEL TENORIO CAVALCANTI | E13: -5300 | F13: EVENTO | G13: 46086 | H13: 79978 | J13: HAPPY HOUR | K13: 114441-3688RC | L13: RUBENS SHIN | M13: TRADER | N13: =VLOOKUP(H13,Clientes!B:D,3,) -> CREDIT SUISSE (BRASIL) S/A CTVM
A14: =CONCATENATE($J$1,J14,$I$3,M14,$I$3,L14,$I$1,K14,$I$2) -> DESPESA DE REPRESENTAÇÃO - JANTAR-TRADER-LUCAS JOSA (100402-3688AF) | B14: 46082 | C14: 817991 | D14: CLAUDIO DE SOUZA PACINI | E14: -526 | F14: JANTAR | G14: 46086 | H14: 15501 | J14: JANTAR | K14: 100402-3688AF | L14: LUCAS JOSA | M14: TRADER | N14: =VLOOKUP(H14,Clientes!B:D,3,) -> BANCO BTG PACTUAL S/A
A15: =CONCATENATE($J$1,J15,$I$3,M15,$I$3,L15,$I$1,K15,$I$2) -> DESPESA DE REPRESENTAÇÃO - ALUGUEL FLAT -BROKER-CHRISTIANO MARCONDES DE BARROS LIMA (AGENDA 40667) | B15: 46082 | C15: 817991 | D15: CHRISTIANO MARCONDES DE BARROS LIMA | E15: -1337.0475 | F15: HOSPEDAGEM | G15: 46084 | H15: 1170 | J15: ALUGUEL FLAT | K15: AGENDA 40667 | L15: CHRISTIANO MARCONDES DE BARROS LIMA | M15: BROKER | N15: =VLOOKUP(H15,Clientes!B:D,3,) -> BGC LIQUIDEZ DTVM LTDA
... A163: =CONCATENATE($J$1,J163,$I$3,M163,$I$3,L163,$I$1,K163,$I$2) -> DESPESA DE REPRESENTAÇÃO - JANTAR COM RENAN SANTOS E KIM KATAGUIRI NO DIA 09/04 NO LOUP-SALES-JOSE ANTONIO DEZENE JUNIOR (AGENDA 41113) | B163: 46082 | C163: 817991 | D163: JOSE ANTONIO DEZENE JUNIOR | E163: -2147 | F163: JANTAR | G163: 46111 | H163: 1170 | J163: JANTAR COM RENAN SANTOS E KIM KATAGUIRI NO DIA 09/04 NO LOUP | K163: AGENDA 41113 | L163: JOSE ANTONIO DEZENE JUNIOR | M163: SALES | N163: =VLOOKUP(H163,Clientes!B:D,3,) -> BGC LIQUIDEZ DTVM LTDA
A164: =CONCATENATE($J$1,J164,$I$3,M164,$I$3,L164,$I$1,K164,$I$2) -> DESPESA DE REPRESENTAÇÃO - -- () | B164: 46082 | C164: 817991
A165: =CONCATENATE($J$1,J165,$I$3,M165,$I$3,L165,$I$1,K165,$I$2) -> DESPESA DE REPRESENTAÇÃO - -- () | B165: 46082 | C165: 817991
A166: =CONCATENATE($J$1,J166,$I$3,M166,$I$3,L166,$I$1,K166,$I$2) -> DESPESA DE REPRESENTAÇÃO - -- () | B166: 46082 | C166: 817991
A167: =CONCATENATE($J$1,J167,$I$3,M167,$I$3,L167,$I$1,K167,$I$2) -> DESPESA DE REPRESENTAÇÃO - -- () | B167: 46082 | C167: 817991

Sheet ABR
A1: HISTORICO | B1: DATA COMPETENCIA | C1: CONTA CONTABIL | D1: BROKER | E1: VALOR | F1: FORNECEDOR | G1: DATA LANCAMENTO | H1: CLIENTE | I1: ( | J1: DESPESA DE REPRESENTAÇÃO - | K1: CODIGO | L1: CONVIDADO | M1: CARGO DO CONVIDADO | N1: RAZÃO SOCIAL
A2: =CONCATENATE($J$1,J2,$I$3,M2,$I$3,L2,$I$1,K2,$I$2) -> DESPESA DE REPRESENTAÇÃO - COMPRA DE 5 CAMISAS DO BRASIL PARA CLIENTESBROKERWESLEY MARQUES DA SILVA (133624-3688RU | B2: 46113 | C2: 817991 | D2: WESLEY MARQUES DA SILVA | E2: -2203.93 | F2: OUTROS | G2: 46114 | H2: 1170 | J2: COMPRA DE 5 CAMISAS DO BRASIL PARA CLIENTES | K2: 133624-3688RU | L2: WESLEY MARQUES DA SILVA | M2: BROKER | N2: =VLOOKUP(H2,Clientes!B:D,3,) -> BGC LIQUIDEZ DTVM LTDA
A3: =CONCATENATE($J$1,J3,$I$3,M3,$I$3,L3,$I$1,K3,$I$2) -> DESPESA DE REPRESENTAÇÃO - PESONALIZAÇÃO CAMISETAS DO BRASILBROKERWESLEY MARQUES DA SILVA (111714-3688PO | B3: 46113 | C3: 817991 | D3: WESLEY MARQUES DA SILVA | E3: -622.8 | F3: OUTROS | G3: 46134 | H3: 1170 | J3: PESONALIZAÇÃO CAMISETAS DO BRASIL | K3: 111714-3688PO | L3: WESLEY MARQUES DA SILVA | M3: BROKER | N3: =VLOOKUP(H3,Clientes!B:D,3,) -> BGC LIQUIDEZ DTVM LTDA
A4: =CONCATENATE($J$1,J4,$I$3,M4,$I$3,L4,$I$1,K4,$I$2) -> DESPESA DE REPRESENTAÇÃO - ALMOÇOTRADERBRUNO SAVARIS (120157-3688RP | B4: 46113 | C4: 817991 | D4: RODRIGO PENTAGNA | E4: -463 | F4: ALMOÇO | G4: 46114 | H4: 83063 | J4: ALMOÇO | K4: 120157-3688RP | L4: BRUNO SAVARIS | M4: TRADER | N4: =VLOOKUP(H4,Clientes!B:D,3,) -> SCHONFELD STRATEGIC ADVISORS BRAZIL LTDA.
A5: =CONCATENATE($J$1,J5,$I$3,M5,$I$3,L5,$I$1,K5,$I$2) -> DESPESA DE REPRESENTAÇÃO - ALMOÇOTRADERNICOLE BENINNI (144822-3688RP | B5: 46113 | C5: 817991 | D5: RODRIGO PENTAGNA | E5: -966 | F5: ALMOÇO | G5: 46121 | H5: 83074 | J5: ALMOÇO | K5: 144822-3688RP | L5: NICOLE BENINNI | M5: TRADER | N5: =VLOOKUP(H5,Clientes!B:D,3,) -> UBS BRASIL ADMINISTRADORA DE VALORES MOBILIARIOS LTDA
A6: =CONCATENATE($J$1,J6,$I$3,M6,$I$3,L6,$I$1,K6,$I$2) -> DESPESA DE REPRESENTAÇÃO - ALMOÇOTRADERYEONG TAE LEE (101017-3688RF | B6: 46113 | C6: 817991 | D6: RICARDO FERREIRA DA COSTA | E6: -554 | F6: ALMOÇO | G6: 46114 | H6: 43059 | I6: ) | J6: ALMOÇO | K6: 101017-3688RF | L6: YEONG TAE LEE | M6: TRADER | N6: =VLOOKUP(H6,Clientes!B:D,3,) -> BANCO FIBRA S/A
A7: =CONCATENATE($J$1,J7,$I$3,M7,$I$3,L7,$I$1,K7,$I$2) -> DESPESA DE REPRESENTAÇÃO - PASSAGEM SÃO PAULO X BRASÍLIABROKERRICARDO ANDRE VASCONCELOS RAMOS (AGENDA 41173 | B7: 46113 | C7: 817991 | D7: RICARDO ANDRE VASCONCELOS RAMOS | E7: -842.53 | F7: LOCOMOÇÃO | G7: 46120 | H7: 1170 | J7: PASSAGEM SÃO PAULO X BRASÍLIA | K7: AGENDA 41173 | L7: RICARDO ANDRE VASCONCELOS RAMOS | M7: BROKER | N7: =VLOOKUP(H7,Clientes!B:D,3,) -> BGC LIQUIDEZ DTVM LTDA
A8: =CONCATENATE($J$1,J8,$I$3,M8,$I$3,L8,$I$1,K8,$I$2) -> DESPESA DE REPRESENTAÇÃO - COMPRA DE 3 CAMISAS DO BRASIL PARA CLIENTESBROKERRICARDO ANDRE VASCONCELOS RAMOS (133624-3688RU | B8: 46113 | C8: 817991 | D8: RICARDO ANDRE VASCONCELOS RAMOS | E8: -1322.36 | F8: OUTROS | G8: 46114 | H8: 1170 | J8: COMPRA DE 3 CAMISAS DO BRASIL PARA CLIENTES | K8: 133624-3688RU | L8: RICARDO ANDRE VASCONCELOS RAMOS | M8: BROKER | N8: =VLOOKUP(H8,Clientes!B:D,3,) -> BGC LIQUIDEZ DTVM LTDA
A9: =CONCATENATE($J$1,J9,$I$3,M9,$I$3,L9,$I$1,K9,$I$2) -> DESPESA DE REPRESENTAÇÃO - HAPPY HOURTRADERALEXANDRE AUGUSTO B RODRIGUES (090034-3688RR | B9: 46113 | C9: 817991 | D9: RICARDO ANDRE VASCONCELOS RAMOS | E9: -1700 | F9: EVENTO | G9: 46121 | H9: 81565 | J9: HAPPY HOUR | K9: 090034-3688RR | L9: ALEXANDRE AUGUSTO B RODRIGUES | M9: TRADER | N9: =VLOOKUP(H9,Clientes!B:D,3,) -> SPX GESTAO DE RECURSOS LTDA
A10: =CONCATENATE($J$1,J10,$I$3,M10,$I$3,L10,$I$1,K10,$I$2) -> DESPESA DE REPRESENTAÇÃO - INGRESSOS PARA O MANIFESTO MUSICAL SÃO PAULOTRADERCARLOS R DE MENEZES JUNIOR (084826-3688RR | B10: 46113 | C10: 817991 | D10: RICARDO ANDRE VASCONCELOS RAMOS | E10: -2340 | F10: EVENTO | G10: 46121 | H10: 79258 | J10: INGRESSOS PARA O MANIFESTO MUSICAL SÃO PAULO | K10: 084826-3688RR | L10: CARLOS R DE MENEZES JUNIOR | M10: TRADER | N10: =VLOOKUP(H10,Clientes!B:D,3,) -> ITAU UNIBANCO S/A
A11: =CONCATENATE($J$1,J11,$I$3,M11,$I$3,L11,$I$1,K11,$I$2) -> DESPESA DE REPRESENTAÇÃO - HAPPY HOURTRADERALESSANDRO EZEQUIEL JUNIOR (085619-3688RR | B11: 46113 | C11: 817991 | D11: RICARDO ANDRE VASCONCELOS RAMOS | E11: -2962.41 | F11: EVENTO | G11: 46121 | H11: 14479 | J11: HAPPY HOUR | K11: 085619-3688RR | L11: ALESSANDRO EZEQUIEL JUNIOR | M11: TRADER | N11: =VLOOKUP(H11,Clientes!B:D,3,) -> BANCO SANTANDER (BRASIL) S/A
A12: =CONCATENATE($J$1,J12,$I$3,M12,$I$3,L12,$I$1,K12,$I$2) -> DESPESA DE REPRESENTAÇÃO - INGRESSOS SHOW "HISTÓRIAS SÃO PAULO" NO ALLIANZ PARQUETRADERJOAO KHOURI (085411-3688RR | B12: 46113 | C12: 817991 | D12: RICARDO ANDRE VASCONCELOS RAMOS | E12: -2984.96 | F12: EVENTO | G12: 46121 | H12: 144548 | J12: INGRESSOS SHOW "HISTÓRIAS SÃO PAULO" NO ALLIANZ PARQUE | K12: 085411-3688RR | L12: JOAO KHOURI | M12: TRADER | N12: =VLOOKUP(H12,Clientes!B:D,3,) -> ABSOLUTE GESTAO DE INVESTIMENTOS LTDA
A13: =CONCATENATE($J$1,J13,$I$3,M13,$I$3,L13,$I$1,K13,$I$2) -> DESPESA DE REPRESENTAÇÃO - ALMOÇOTRADERCARLOS R DE MENEZES JUNIOR (084637-3688RR | B13: 46113 | C13: 817991 | D13: RICARDO ANDRE VASCONCELOS RAMOS | E13: -562.51 | F13: ALMOÇO | G13: 46121 | H13: 79258 | J13: ALMOÇO | K13: 084637-3688RR | L13: CARLOS R DE MENEZES JUNIOR | M13: TRADER | N13: =VLOOKUP(H13,Clientes!B:D,3,) -> ITAU UNIBANCO S/A
A14: =CONCATENATE($J$1,J14,$I$3,M14,$I$3,L14,$I$1,K14,$I$2) -> DESPESA DE REPRESENTAÇÃO - CAMISAS DO BRASIL PARA CLIENTES TRADERCARLOS R DE MENEZES JUNIOR (104520-3688RR | B14: 46113 | C14: 817991 | D14: RICARDO ANDRE VASCONCELOS RAMOS | E14: -2699.94 | F14: EVENTO | G14: 46121 | H14: 79258 | J14: CAMISAS DO BRASIL PARA CLIENTES | K14: 104520-3688RR | L14: CARLOS R DE MENEZES JUNIOR | M14: TRADER | N14: =VLOOKUP(H14,Clientes!B:D,3,) -> ITAU UNIBANCO S/A
A15: =CONCATENATE($J$1,J15,$I$3,M15,$I$3,L15,$I$1,K15,$I$2) -> DESPESA DE REPRESENTAÇÃO - ALMOÇOTRADERJOAO KHOURI (145714-3688RR | B15: 46113 | C15: 817991 | D15: RICARDO ANDRE VASCONCELOS RAMOS | E15: -461.37 | F15: ALMOÇO | G15: 46128 | H15: 144548 | J15: ALMOÇO | K15: 145714-3688RR | L15: JOAO KHOURI | M15: TRADER | N15: =VLOOKUP(H15,Clientes!B:D,3,) -> ABSOLUTE GESTAO DE INVESTIMENTOS LTDA
A16: =CONCATENATE($J$1,J16,$I$3,M16,$I$3,L16,$I$1,K16,$I$2) -> DESPESA DE REPRESENTAÇÃO - COBERTURA FOTOGRÁFICA KAITAI NO OIZUMI SUSHIBROKERRICARDO ANDRE VASCONCELOS RAMOS (AGENDA 41493 | B16: 46113 | C16: 817991 | D16: RICARDO ANDRE VASCONCELOS RAMOS | E16: -500 | F16: EVENTO | G16: 46129 | H16: 1170 | J16: COBERTURA FOTOGRÁFICA KAITAI NO OIZUMI SUSHI | K16: AGENDA 41493 | L16: RICARDO ANDRE VASCONCELOS RAMOS | M16: BROKER | N16: =VLOOKUP(H16,Clientes!B:D,3,) -> BGC LIQUIDEZ DTVM LTDA
A17: =CONCATENATE($J$1,J17,$I$3,M17,$I$3,L17,$I$1,K17,$I$2) -> DESPESA DE REPRESENTAÇÃO - PESONALIZAÇÃO CAMISETAS DO BRASILBROKERRICARDO ANDRE VASCONCELOS RAMOS (111714-3688PO | B17: 46113 | C17: 817991 | D17: RICARDO ANDRE VASCONCELOS RAMOS | E17: -622.8 | F17: OUTROS | G17: 46134 | H17: 1170 | J17: PESONALIZAÇÃO CAMISETAS DO BRASIL | K17: 111714-3688PO | L17: RICARDO ANDRE VASCONCELOS RAMOS | M17: BROKER | N17: =VLOOKUP(H17,Clientes!B:D,3,) -> BGC LIQUIDEZ DTVM LTDA
A18: =CONCATENATE($J$1,J18,$I$3,M18,$I$3,L18,$I$1,K18,$I$2) -> DESPESA DE REPRESENTAÇÃO - JANTARTRADERHUGO ALVES (090737-3688RR | B18: 46113 | C18: 817991 | D18: RICARDO ANDRE VASCONCELOS RAMOS | E18: -1054.58 | F18: JANTAR | G18: 46134 | H18: 79475 | J18: JANTAR | K18: 090737-3688RR | L18: HUGO ALVES | M18: TRADER | N18: =VLOOKUP(H18,Clientes!B:D,3,) -> CAIXA ECONOMICA FEDERAL
... A114: =CONCATENATE($J$1,J114,$I$3,M114,$I$3,L114,$I$1,K114,$I$2) -> DESPESA DE REPRESENTAÇÃO - ALMOÇOTRADERLEONARDO TARALLO (174553-3688FR | B114: 46113 | C114: 817991 | D114: FELIPE MEIRELLES RACCAH | E114: -406.8 | F114: ALMOÇO | G114: 46142 | H114: 12413 | J114: ALMOÇO | K114: 174553-3688FR | L114: LEONARDO TARALLO | M114: TRADER | N114: =VLOOKUP(H114,Clientes!B:D,3,) -> KAPITALO INVESTIMENTOS LTDA
A115: =CONCATENATE($J$1,J115,$I$3,M115,$I$3,L115,$I$1,K115,$I$2) -> DESPESA DE REPRESENTAÇÃO - ALMOÇO FILIPE SABARÁ E DANILO CAFFAROTRADERDANILO CAFFARO (142203-3688FT | B115: 46113 | C115: 817991 | D115: FELIPE DE SA TAVARES | E115: -1089.32 | F115: ALMOÇO | G115: 46114 | H115: 1170 | I115: - | J115: ALMOÇO FILIPE SABARÁ E DANILO CAFFARO | K115: 142203-3688FT | L115: DANILO CAFFARO | M115: TRADER | N115: =VLOOKUP(H115,Clientes!B:D,3,) -> BGC LIQUIDEZ DTVM LTDA
A116: =CONCATENATE($J$1,J116,$I$3,M116,$I$3,L116,$I$1,K116,$I$2) -> DESPESA DE REPRESENTAÇÃO - CAFÉ DA MANHÃTRADERRODRIGO SANTANA FERREIRA (141120-3688FT | B116: 46113 | C116: 817991 | D116: FELIPE DE SA TAVARES | E116: -2932.35 | F116: CAFÉ DA MANHÃ | G116: 46114 | H116: 14479 | J116: CAFÉ DA MANHÃ | K116: 141120-3688FT | L116: RODRIGO SANTANA FERREIRA | M116: TRADER | N116: =VLOOKUP(H116,Clientes!B:D,3,) -> BANCO SANTANDER (BRASIL) S/A
A117: =CONCATENATE($J$1,J117,$I$3,M117,$I$3,L117,$I$1,K117,$I$2) -> DESPESA DE REPRESENTAÇÃO - CAFÉ DA MANHÃTRADERROGERIO MATTEDI FOLSTER (141813-3688FT | B117: 46113 | C117: 817991 | D117: FELIPE DE SA TAVARES | E117: -187.5 | F117: CAFÉ DA MANHÃ | G117: 46114 | H117: 80375 | J117: CAFÉ DA MANHÃ | K117: 141813-3688FT | L117: ROGERIO MATTEDI FOLSTER | M117: TRADER | N117: =VLOOKUP(H117,Clientes!B:D,3,) -> ITAU UNIBANCO S/A
A118: =CONCATENATE($J$1,J118,$I$3,M118,$I$3,L118,$I$1,K118,$I$2) -> DESPESA DE REPRESENTAÇÃO - PASSAGEM RIO DE JANEIRO X SÃO PAULOBROKERFELIPE DE SA TAVARES (AGENDA 41265 | B118: 46113 | C118: 817991 | D118: FELIPE DE SA TAVARES | E118: -1269.41 | F118: LOCOMOÇÃO | G118: 46122 | H118: 1170 | J118: PASSAGEM RIO DE JANEIRO X SÃO PAULO | K118: AGENDA 41265 | L118: FELIPE DE SA TAVARES | M118: BROKER | N118: =VLOOKUP(H118,Clientes!B:D,3,) -> BGC LIQUIDEZ DTVM LTDA
A119: =CONCATENATE($J$1,J119,$I$3,M119,$I$3,L119,$I$1,K119,$I$2) -> DESPESA DE REPRESENTAÇÃO - ALMOÇOTRADERTHOMAS CITRIN (140515-3688FB | B119: 46113 | C119: 817991 | D119: FELIPE DE ANDRADE BASILE | E119: -1767 | F119: ALMOÇO | G119: 46128 | H119: 81718 | J119: ALMOÇO | K119: 140515-3688FB | L119: THOMAS CITRIN | M119: TRADER | N119: =VLOOKUP(H119,Clientes!B:D,3,) -> QUANTIQUE M3 INVESTMENTS LTDA
A120: =CONCATENATE($J$1,J120,$I$3,M120,$I$3,L120,$I$1,K120,$I$2) -> DESPESA DE REPRESENTAÇÃO - COMPRA DE 4 CAMISAS DO BRASIL PARA CLIENTESBROKERFABIO SOARES PFAENDER (133624-3688RU | B120: 46113 | C120: 817991 | D120: FABIO SOARES PFAENDER | E120: -1763.14 | F120: OUTROS | G120: 46114 | H120: 1170 | J120: COMPRA DE 4 CAMISAS DO BRASIL PARA CLIENTES | K120: 133624-3688RU | L120: FABIO SOARES PFAENDER | M120: BROKER | N120: =VLOOKUP(H120,Clientes!B:D,3,) -> BGC LIQUIDEZ DTVM LTDA
A121: =CONCATENATE($J$1,J121,$I$3,M121,$I$3,L121,$I$1,K121,$I$2) -> DESPESA DE REPRESENTAÇÃO - PASSAGEM RIO DE JANEIRO X SÃO PAULOCEOERMINIO OLIVI LUCCI (AGENDA 41309 | B121: 46113 | C121: 817991 | D121: ERMINIO OLIVI LUCCI | E121: -1057.24 | F121: LOCOMOÇÃO | G121: 46127 | H121: 1170 | J121: PASSAGEM RIO DE JANEIRO X SÃO PAULO | K121: AGENDA 41309 | L121: ERMINIO OLIVI LUCCI | M121: CEO | N121: =VLOOKUP(H121,Clientes!B:D,3,) -> BGC LIQUIDEZ DTVM LTDA
A122: =CONCATENATE($J$1,J122,$I$3,M122,$I$3,L122,$I$1,K122,$I$2) -> DESPESA DE REPRESENTAÇÃO - PASSAGEM RIO DE JANEIRO X SÃO PAULOCEOERMINIO OLIVI LUCCI (AGENDA 41310 | B122: 46113 | C122: 817991 | D122: ERMINIO OLIVI LUCCI | E122: -3588.43 | F122: LOCOMOÇÃO | G122: 46127 | H122: 1170 | J122: PASSAGEM RIO DE JANEIRO X SÃO PAULO | K122: AGENDA 41310 | L122: ERMINIO OLIVI LUCCI | M122: CEO | N122: =VLOOKUP(H122,Clientes!B:D,3,) -> BGC LIQUIDEZ DTVM LTDA
A123: =CONCATENATE($J$1,J123,$I$3,M123,$I$3,L123,$I$1,K123,$I$2) -> DESPESA DE REPRESENTAÇÃO - PASSAGEM SÃO PAULO X MIAMICEOERMINIO OLIVI LUCCI (AGENDA 41643 | B123: 46113 | C123: 817991 | D123: ERMINIO OLIVI LUCCI | E123: -37425.87 | F123: LOCOMOÇÃO | G123: 46142 | H123: 1170 | J123: PASSAGEM SÃO PAULO X MIAMI | K123: AGENDA 41643 | L123: ERMINIO OLIVI LUCCI | M123: CEO | N123: =VLOOKUP(H123,Clientes!B:D,3,) -> BGC LIQUIDEZ DTVM LTDA
A124: =CONCATENATE($J$1,J124,$I$3,M124,$I$3,L124,$I$1,K124,$I$2) -> DESPESA DE REPRESENTAÇÃO - PRESENTE DE ANIVERSARIO DA SECRETARIA ANNA TAPIASSECRETARIAANNA CAROLINA ABRUNHOSA TAPIAS (AGENDA 41176 | B124: 46113 | C124: 817991 | D124: ERMINIO OLIVI LUCCI | E124: -989.9 | F124: OUTROS | G124: 46114 | H124: 1170 | J124: PRESENTE DE ANIVERSARIO DA SECRETARIA ANNA TAPIAS | K124: AGENDA 41176 | L124: ANNA CAROLINA ABRUNHOSA TAPIAS | M124: SECRETARIA | N124: =VLOOKUP(H124,Clientes!B:D,3,) -> BGC LIQUIDEZ DTVM LTDA
A125: =CONCATENATE($J$1,J125,$I$3,M125,$I$3,L125,$I$1,K125,$I$2) -> DESPESA DE REPRESENTAÇÃO - MENSALIDADE DA ASSOCIAÇÃO AO WTC BUSSINESS CLUBCEOERMINIO OLIVI LUCCI (AGENDA 41241 | B125: 46113 | C125: 817991 | D125: ERMINIO OLIVI LUCCI | E125: -2000 | F125: OUTROS | G125: 46132 | H125: 1170 | J125: MENSALIDADE DA ASSOCIAÇÃO AO WTC BUSSINESS CLUB | K125: AGENDA 41241 | L125: ERMINIO OLIVI LUCCI | M125: CEO | N125: =VLOOKUP(H125,Clientes!B:D,3,) -> BGC LIQUIDEZ DTVM LTDA
A126: =CONCATENATE($J$1,J126,$I$3,M126,$I$3,L126,$I$1,K126,$I$2) -> DESPESA DE REPRESENTAÇÃO - HOSPEDAGEM NO HOTEL EM NOVA YORKCEOERMINIO OLIVI LUCCI (AGENDA 41298 | B126: 46113 | C126: 817991 | D126: ERMINIO OLIVI LUCCI | E126: -7853.99 | F126: HOSPEDAGEM | G126: 46119 | H126: 1170 | J126: HOSPEDAGEM NO HOTEL EM NOVA YORK | K126: AGENDA 41298 | L126: ERMINIO OLIVI LUCCI | M126: CEO | N126: =VLOOKUP(H126,Clientes!B:D,3,) -> BGC LIQUIDEZ DTVM LTDA
A127: =CONCATENATE($J$1,J127,$I$3,M127,$I$3,L127,$I$1,K127,$I$2) -> DESPESA DE REPRESENTAÇÃO - HOSPEDAGEM NO HOTEL EM NOVA YORKCEOERMINIO OLIVI LUCCI (AGENDA 41298 | B127: 46113 | C127: 817991 | D127: ERMINIO OLIVI LUCCI | E127: -3185.14 | F127: HOSPEDAGEM | G127: 46119 | H127: 1170 | J127: HOSPEDAGEM NO HOTEL EM NOVA YORK | K127: AGENDA 41298 | L127: ERMINIO OLIVI LUCCI | M127: CEO | N127: =VLOOKUP(H127,Clientes!B:D,3,) -> BGC LIQUIDEZ DTVM LTDA
... A199: =CONCATENATE($J$1,J199,$I$3,M199,$I$3,L199,$I$1,K199,$I$2) -> DESPESA DE REPRESENTAÇÃO - ALMOÇOTRADERANTONIO JOAQUIM DE M ANDRADE (145217-3688AS | B199: 46113 | C199: 817991 | D199: ALEXANDRE BRENO STEVENS | E199: -531 | F199: ALMOÇO | G199: 46134 | H199: 15501 | J199: ALMOÇO | K199: 145217-3688AS | L199: ANTONIO JOAQUIM DE M ANDRADE | M199: TRADER | N199: =VLOOKUP(H199,Clientes!B:D,3,) -> BANCO BTG PACTUAL S/A

Sheet MAI
A1: HISTORICO | B1: DATA COMPETENCIA | C1: CONTA CONTABIL | D1: BROKER | E1: VALOR | F1: FORNECEDOR | G1: DATA LANCAMENTO | H1: CLIENTE | I1: ( | J1: DESPESA DE REPRESENTAÇÃO - | K1: CODIGO | L1: CONVIDADO | M1: CARGO DO CONVIDADO | N1: RAZÃO SOCIAL
A2: =CONCATENATE($J$1,J2,$I$3,M2,$I$3,L2,$I$1,K2,$I$2) -> DESPESA DE REPRESENTAÇÃO - THE UNION HOTEL BRASILIA -BROKER-JUAREZ JOAQUIM DE LACERDA (AGENDA 41649) | B2: 46143 | C2: 817991 | D2: JUAREZ JOAQUIM DE LACERDA | E2: -826.03 | F2: HOSPEDAGEM | G2: 46146 | H2: 1170 | I2: ) | J2: THE UNION HOTEL BRASILIA | K2: AGENDA 41649 | L2: JUAREZ JOAQUIM DE LACERDA | M2: BROKER | N2: =VLOOKUP(H2,Clientes!B:D,3,) -> BGC LIQUIDEZ DTVM LTDA
A3: =CONCATENATE($J$1,J3,$I$3,M3,$I$3,L3,$I$1,K3,$I$2) -> DESPESA DE REPRESENTAÇÃO - HAPPY HOUR -TRADER-LEONARDO MASSAHIKO NAKAJIMA (132145-3688RM) | B3: 46143 | C3: 817991 | D3: RODRIGO MOURA MARQUES | E3: -2915.39 | F3: EVENTO | G3: 46146 | H3: 81501 | I3: - | J3: HAPPY HOUR | K3: 132145-3688RM | L3: LEONARDO MASSAHIKO NAKAJIMA | M3: TRADER | N3: =VLOOKUP(H3,Clientes!B:D,3,) -> PORTO SEGURO INVESTIMENTOS LTDA
A4: =CONCATENATE($J$1,J4,$I$3,M4,$I$3,L4,$I$1,K4,$I$2) -> DESPESA DE REPRESENTAÇÃO - ALMOÇO-TRADER-FREDERIC CAMPOS BROWN (141012-3688AC) | B4: 46143 | C4: 817991 | D4: ALEXANDRE DA COSTA SOARES | E4: -619 | F4: ALMOÇO | G4: 46149 | H4: 79258 | J4: ALMOÇO | K4: 141012-3688AC | L4: FREDERIC CAMPOS BROWN | M4: TRADER | N4: =VLOOKUP(H4,Clientes!B:D,3,) -> ITAU UNIBANCO S/A
A5: =CONCATENATE($J$1,J5,$I$3,M5,$I$3,L5,$I$1,K5,$I$2) -> DESPESA DE REPRESENTAÇÃO - ALMOÇO-TRADER-RAFAEL ASSED (153602-3688BG) | B5: 46143 | C5: 817991 | D5: JOSE MAURICIO GOMES TEIXEIRA | E5: -408 | F5: ALMOÇO | G5: 46149 | H5: 80218 | J5: ALMOÇO | K5: 153602-3688BG | L5: RAFAEL ASSED | M5: TRADER | N5: =VLOOKUP(H5,Clientes!B:D,3,) -> OPPORTUNITY GESTAO DE INVESTIMENTOS E RECURSOS LTDA
A6: =CONCATENATE($J$1,J6,$I$3,M6,$I$3,L6,$I$1,K6,$I$2) -> DESPESA DE REPRESENTAÇÃO - JANTAR-TRADER-GUILHERME ALVES DE PAULA (093425-3688BG) | B6: 46143 | C6: 817991 | D6: JOSE MAURICIO GOMES TEIXEIRA | E6: -828 | F6: JANTAR | G6: 46149 | H6: 81199 | J6: JANTAR | K6: 093425-3688BG | L6: GUILHERME ALVES DE PAULA | M6: TRADER | N6: =VLOOKUP(H6,Clientes!B:D,3,) -> BANCO ORIGINAL S/A
